Workbook

Sheet 设备清单
B1: 设备编号 | C1: 内部编号 | D1: 设备名称 | E1: 出厂编号 | F1: Equipment | G1: 制造厂商 | H1: 型号 | I1: 设备尺寸 | J1: 主要参数 | K1: 能耗 | L1: 投入使用时间 | M1: 到货日期 | N1: 放置地点 | O1: 负责人 | P1: 授权设备分类 | Q1: 校准机构 | R1: 校准 地点 | S1: 校准有效期 | T1: 上次校准有效期 | U1: 校准时间 | V1: 计划校准时间 | W1: 期间核查 | X1: 溯源计划 | Y1: 校准计划 | Z1: 校准状态 | AA1: 备注
A2: SHAED-A | B2: SHAED-A050 | C2: TTE20192958 | D2: 电子万能试验机 | E2: 17011203 | F2: Universal material testing machine | G2: 美特斯工业系统（中国）有限公司 | H2: E43.104 | I2: NA | J2: 10kg/100kg/500kg (0.001~500)mm/min | K2: NA | L2: =VLOOKUP(C2,设备卡片列表!A:I,6,FALSE) -> 2020-03-01 | M2: 2019 | N2: 联东 | O2: 王林华 | P2: A | Q2: CTI | R2: 现场 | S2: 一年 | T2: 45993 | U2: 45992 | V2: =U2+364 -> 46356 | W2: NA | X2: ASY-01
A3: SHAED-A | B3: SHAED-A051 | C3: TTE202608429 | D3: 电子万能试验机 | E3: LE2604051 | F3: Universal material testing machine | G3: 力试 | H3: LD24.204 | J3: 100/1000/20000N (0.001~500)mm/min | M3: 2026 | N3: 联东 | O3: 王林华 | P3: A | Q3: CTI | R3: 现场 | U3: 46220 | V3: =U3+364 -> 46584 | W3: NA | X3: ASY-02
A4: SHAED-C | B4: SHAED-C001 | C4: TTE20192945 | D4: 温湿度环境箱 | E4: 54260024360080 | F4: Temperature and humidity chamber | G4: 伟思富奇（太仓） | H4: C7-600E series | I4: W790 x D750 x H950mm=600L | J4: 温度：-70~+150 °C；湿度：15% ~98 % RH（+ 10 ~ + 95 °C） 升降温速率：±2℃/min 耐功耗：2kw | K4: 21A，10.1KW | L4: =VLOOKUP(C4,设备卡片列表!A:I,6,FALSE) -> 2019-11-05 | M4: 2019 | N4: 联东 | O4: 徐东敏 | P4: A | Q4: CTI | R4: 现场 | S4: 一年 | T4: 45943 | U4: 45939 | V4: =U4+364 -> 46303 | W4: =U4+183 -> 46122 | X4: CSY-01
A5: SHAED-C | B5: SHAED-C002 | C5: TTE20192946 | D5: 温湿度环境箱 | E5: 54260024360060 | F5: Temperature and humidity chamber | G5: 伟思富奇（太仓） | H5: C7-600E series | I5: W790 x D750 x H950mm=600L | J5: 温度：-70~+150 °C；湿度：15% ~98 % RH（+ 10 ~ + 95 °C） 升降温速率：±2℃/min 耐功耗：2kw | K5: 21A，10.1KW | L5: =VLOOKUP(C5,设备卡片列表!A:I,6,FALSE) -> 2019-11-05 | M5: 2019 | N5: 联东 | O5: 徐东敏 | P5: A | Q5: CTI | R5: 现场 | S5: 一年 | T5: 45943 | U5: 45939 | V5: =U5+364 -> 46303 | W5: =U5+183 -> 46122 | X5: CSY-01
A6: SHAED-C | B6: SHAED-C003 | C6: TTE20192947 | D6: 温湿度环境箱 | E6: 54260024360090 | F6: Temperature and humidity chamber | G6: 伟思富奇（太仓） | H6: C7-600E series | I6: W790 x D750 x H950mm=600L | J6: 温度：-70~+150 °C；湿度：15% ~98 % RH（+ 10 ~ + 95 °C） 升降温速率：±2℃/min 耐功耗：2kw | K6: 21A，10.1KW | L6: =VLOOKUP(C6,设备卡片列表!A:I,6,FALSE) -> 2019-11-05 | M6: 2019 | O6: 徐东敏 | P6: A | Q6: CTI | R6: 现场 | S6: 一年 | T6: 45943 | U6: 45939 | V6: =U6+364 -> 46303 | W6: =U6+183 -> 46122 | X6: CSY-01
A7: SHAED-C | B7: SHAED-C004 | C7: TTE20192948 | D7: 温湿度环境箱 | E7: 54260024360070 | F7: Temperature and humidity chamber | G7: 伟思富奇（太仓） | H7: C7-600E series | I7: W790 x D750 x H950mm=600L | J7: 温度：-70~+150 °C；湿度：15% ~98 % RH（+ 10 ~ + 95 °C） 升降温速率：±2℃/min 耐功耗：2kw | K7: 21A，10.1KW | L7: =VLOOKUP(C7,设备卡片列表!A:I,6,FALSE) -> 2019-11-05 | M7: 2019 | O7: 徐东敏 | P7: A | Q7: CTI | R7: 现场 | S7: 一年 | T7: 45943 | U7: 45939 | V7: =U7+364 -> 46303 | W7: =U7+183 -> 46122 | X7: CSY-01
A8: SHAED-C | B8: SHAED-C005 | C8: TTE20192954 | D8: 温湿度环境箱-Pro | E8: 54260024360050 | F8: Temperature and humidity chamber (pro) | G8: 伟思富奇（太仓） | H8: C7-1000E series pro | I8: W1090 x D900 x H950mm=1000L | J8: 温度：-70~+180 °C；湿度：15% ~98 % RH（+ 10 ~ + 95 °C） 升降温速率：±2℃/min Pro 耐功耗：2kw | K8: 25A，14KW | L8: =VLOOKUP(C8,设备卡片列表!A:I,6,FALSE) -> 2019-12-16 | M8: 2019 | P8: A | Q8: CTI | R8: 现场 | S8: 一年 | T8: 45943 | U8: 45939 | V8: =U8+364 -> 46303 | W8: =U8+183 -> 46122 | X8: CSY-02
A9: SHAED-C | B9: SHAED-C006 | C9: TTE20201826 | D9: 环境箱-匹配振动台 | E9: 191379 | F9: Temperature chamber (for vibration equipment) | G9: 重庆阿泰可 | H9: CH1500TCH（水平） | I9: W1200 x D1100 x H1160mm=1531L | J9: 与SHAED-V001匹配 温度：-70~+150 °C 温度偏差：≤±2℃ 温度波动度：≤±0.5℃ 温度均匀度：≤±2℃ 温度变化速率：≥2℃/min | K9: 40A，22KW | L9: =VLOOKUP(C9,设备卡片列表!A:I,6,FALSE) -> 2019-12-26 | M9: 2019 | O9: 张杰 | P9: A | Q9: CTI | R9: 现场 | S9: 一年 | T9: 46282 | U9: 46282 | V9: =U9+364 -> 46646 | W9: =U9+183 -> 46465 | X9: CSY-03
A10: SHAED-C | B10: SHAED-C007 | C10: TTE20193199 | D10: 环境箱-匹配振动台 | E10: 19178018 | F10: Temperature chamber (for vibration equipment) | G10: 广州五所环境仪器有限公司 | H10: CT2970A2 （水平） | I10: W1500 x D1500 x H1300mm=2925L | J10: 与SHAED-V004匹配 温度：-70~+150 °C 温度偏差：优于±1.5℃（≤150℃）；≤±2℃（150~180℃） 温度波动度：≤0.5℃ 温度均匀度：≤2℃ 温度变化速率：≥2℃/min | K10: Max 70A, 38KW | L10: =VLOOKUP(C10,设备卡片列表!A:I,6,FALSE) -> 2019-12-25 | M10: 2019 | O10: 张杰 | P10: A | Q10: CTI | R10: 现场 | S10: 一年 | T10: 46282 | U10: 46281 | V10: =U10+364 -> 46645 | W10: =U10+183 -> 46464 | X10: CSY-03
A11: SHAED-C | B11: SHAED-C008 | C11: TTE20193200 | D11: 环境箱-匹配振动台 | E11: 19178017 | F11: Temperature chamber (for vibration equipment) | G11: 广州五所环境仪器有限公司 | H11: CT2970A2 （垂直） | I11: W1500 x D1500 x H1300mm=2925L | J11: 与SHAED-V005匹配 温度：-70~+150 °C 温度偏差：优于±1.5℃（≤150℃）；≤±2℃（150~180℃） 温度波动度：≤0.5℃ 温度均匀度：≤2℃ 温度变化速率：≥2℃/min | K11: Max 70A, 38KW | L11: =VLOOKUP(C11,设备卡片列表!A:I,6,FALSE) -> 2019-12-25 | M11: 2019 | O11: 张杰 | P11: A | Q11: CTI | R11: 现场 | S11: 一年 | T11: 46282 | U11: 46281 | V11: =U11+364 -> 46645 | W11: =U11+183 -> 46464 | X11: CSY-03
A12: SHAED-C | B12: SHAED-C009 | C12: TTE20193201 | D12: 环境箱-匹配振动台 | E12: 19178019 | F12: Temperature chamber (for vibration equipment) | G12: 广州五所环境仪器有限公司 | H12: CT2970A2 （垂直+水平） | I12: W1500 x D1500 x H1300mm=2925L | J12: 与SHAED-V006匹配 温度：-70~+150 °C 温度偏差：优于±1.5℃（≤150℃）；≤±2℃（150~180℃） 温度波动度：≤0.5℃ 温度均匀度：≤2℃ 温度变化速率：≥2℃/min | K12: Max 70A, 38KW | L12: =VLOOKUP(C12,设备卡片列表!A:I,6,FALSE) -> 2019-12-25 | M12: 2019 | O12: 张杰 | P12: A | Q12: CTI | R12: 现场 | S12: 一年 | T12: 46283 | U12: 46281 | V12: =U12+364 -> 46645 | W12: =U12+183 -> 46464 | X12: CSY-03
A13: SHAED-C | B13: SHAED-C010 | C13: TTE20200975 | D13: 温湿度环境箱 | E13: 54260027280020 | F13: Temperature and humidity chamber | G13: 伟思富奇（太仓） | H13: C7-600E series | I13: W790 x D750 x H950mm=600L | J13: 温度：-70~+150 °C；湿度：15% ~98 % RH（+ 10 ~ + 95 °C） 升降温速率：±2℃/min 耐功耗：2kw | K13: 21A，10.1KW | L13: =VLOOKUP(C13,设备卡片列表!A:I,6,FALSE) -> 2020-07-07 | M13: 2020 | O13: 徐东敏 | P13: A | Q13: CTI | R13: 现场 | S13: 一年 | T13: 46076 | U13: 46065 | V13: =U13+364 -> 46429 | W13: =U13+183 -> 46248 | X13: CSY-01
A14: SHAED-C | B14: SHAED-C011 | C14: TTE20200974 | D14: 温湿度环境箱 | E14: 54260027280010 | F14: Temperature and humidity chamber | G14: 伟思富奇（太仓） | H14: C7-600E series | I14: W790 x D750 x H950mm=600L | J14: 温度：-70~+150 °C；湿度：15% ~98 % RH（+ 10 ~ + 95 °C） 升降温速率：±2℃/min 耐功耗：2kw | K14: 21A，10.1KW | L14: =VLOOKUP(C14,设备卡片列表!A:I,6,FALSE) -> 2020-07-30 | M14: 2020 | O14: 徐东敏 | P14: A | Q14: CTI | R14: 现场 | S14: 一年 | T14: 46126 | U14: 46125 | V14: =U14+364 -> 46489 | W14: =U14+183 -> 46308 | X14: CSY-01
A15: SHAED-C | B15: SHAED-C012 | C15: TTE20192957 | D15: 温湿度环境箱 | E15: 54260027280040 | F15: Temperature and humidity chamber | G15: 伟思富奇（太仓） | H15: C7-1000E series | I15: W1090 x D900 x H950mm=1000L | J15: 温度：-70~+150 °C；湿度：15% ~98 % RH（+ 10 ~ + 95 °C） 升降温速率：±2℃/min 耐功耗：2kw | K15: 25A，14KW | L15: =VLOOKUP(C15,设备卡片列表!A:I,6,FALSE) -> 2020-06-08 | M15: 2020 | P15: A | Q15: CTI | R15: 现场 | S15: 一年 | T15: 46126 | U15: 46125 | V15: =U15+364 -> 46489 | W15: =U15+183 -> 46308 | X15: CSY-01
A16: SHAED-C | B16: SHAED-C013 | C16: TTE20200976 | D16: 温湿度环境箱 | E16: 54260027280030 | F16: Temperature and humidity chamber | G16: 伟思富奇（太仓） | H16: C7-1000E series | I16: W1090 x D900 x H950mm=1000L | J16: 温度：-70~+150 °C；湿度：15% ~98 % RH（+ 10 ~ + 95 °C） 升降温速率：±2℃/min 耐功耗：2kw | K16: 25A，14KW | L16: =VLOOKUP(C16,设备卡片列表!A:I,6,FALSE) -> 2020-06-08 | M16: 2020 | P16: A | Q16: CTI | R16: 现场 | S16: 一年 | T16: 46126 | U16: 46125 | V16: =U16+364 -> 46489 | W16: =U16+183 -> 46308 | X16: CSY-01
A17: SHAED-C | B17: SHAED-C014 | C17: TTE20200977 | D17: 温湿度环境箱 | E17: 54260027280050 | F17: Temperature and humidity chamber | G17: 伟思富奇（太仓） | H17: C7-1000E series | I17: W1090 x D900 x H950mm=1000L | J17: 温度：-70~+150 °C；湿度：15% ~98 % RH（+ 10 ~ + 95 °C） 升降温速率：±2℃/min 耐功耗：2kw | K17: 25A，14KW | L17: =VLOOKUP(C17,设备卡片列表!A:I,6,FALSE) -> 2020-06-08 | M17: 2020 | P17: A | Q17: CTI | R17: 现场 | S17: 一年 | T17: 46076 | U17: 46065 | V17: =U17+364 -> 46429 | W17: =U17+183 -> 46248 | X17: CSY-01
A18: SHAED-C | B18: SHAED-C015 | C18: TTE20192943 | D18: 温湿度环境箱 | E18: 54260024360120 | F18: Temperature and humidity chamber | G18: 伟思富奇（太仓） | H18: C7-1000E series | I18: W1090 x D900 x H950mm=1000L | J18: 温度：-70~+150 °C；湿度：15% ~98 % RH（+ 10 ~ + 95 °C） 升降温速率：±2℃/min 耐功耗：2kw | K18: 25A，14KW | L18: =VLOOKUP(C18,设备卡片列表!A:I,6,FALSE) -> 2020-06-08 | M18: 2020 | P18: A | Q18: CTI | R18: 现场 | S18: 一年 | T18: 46126 | U18: 46115 | V18: =U18+364 -> 46479 | W18: =U18+183 -> 46298 | X18: CSY-01
A19: SHAED-C | B19: SHAED-C016 | C19: TTE20200978 | D19: 温湿度环境箱 | E19: 54260024360150 | F19: Temperature and humidity chamber | G19: 伟思富奇（太仓） | H19: C7-1000E series | I19: W1090 x D900 x H950mm=1000L | J19: 温度：-70~+150 °C；湿度：15% ~98 % RH（+ 10 ~ + 95 °C） 升降温速率：±2℃/min 耐功耗：2kw | K19: 25A，14KW | L19: =VLOOKUP(C19,设备卡片列表!A:I,6,FALSE) -> 2020-06-17 | M19: 2020 | O19: 王林华 | P19: A | Q19: CTI | R19: 现场 | S19: 一年 | T19: 46126 | U19: 46115 | V19: =U19+364 -> 46479 | W19: =U19+183 -> 46298 | X19: CSY-01
A20: SHAED-C | B20: SHAED-C017 | C20: TTE20192955 | D20: 温湿度环境箱 | E20: 54260024360100 | F20: Temperature and humidity chamber | G20: 伟思富奇（太仓） | H20: C7-1000E series | I20: W1090 x D900 x H950mm=1000L | J20: 温度：-70~+150 °C；湿度：15% ~98 % RH（+ 10 ~ + 95 °C） 升降温速率：±2℃/min 耐功耗：2kw | K20: 25A，14KW | L20: =VLOOKUP(C20,设备卡片列表!A:I,6,FALSE) -> 2020-06-03 | M20: 2020 | O20: 王林华 | P20: A | Q20: CTI | R20: 现场 | S20: 一年 | T20: 46126 | U20: 46125 | V20: =U20+364 -> 46489 | W20: =U20+183 -> 46308 | X20: CSY-01
A21: SHAED-C | B21: SHAED-C018 | C21: TTE20192956 | D21: 温湿度环境箱 | E21: 54260024360110 | F21: Temperature and humidity chamber | G21: 伟思富奇（太仓） | H21: C7-1000E series | I21: W1090 x D900 x H950mm=1000L | J21: 温度：-70~+150 °C；湿度：15% ~98 % RH（+ 10 ~ + 95 °C） 升降温速率：±2℃/min 耐功耗：2kw | K21: 25A，14KW | L21: =VLOOKUP(C21,设备卡片列表!A:I,6,FALSE) -> 2020-06-08 | M21: 2020 | O21: 王林华 | P21: A | Q21: CTI | R21: 现场 | S21: 一年 | T21: 46076 | U21: 46065 | V21: =U21+364 -> 46429 | W21: =U21+183 -> 46248 | X21: CSY-01
A22: SHAED-C | B22: SHAED-C019 | C22: TTE20192949 | D22: 温湿度环境箱 | E22: 54260024360130 | F22: Temperature and humidity chamber | G22: 伟思富奇（太仓） | H22: C7-1500E series | I22: W1090 x D1430 x H950mm=1500L | J22: 温度：-70~+150 °C；湿度：15% ~98 % RH（+ 10 ~ + 95 °C） 升降温速率：±2℃/min 耐功耗：2kw | K22: 29A，15.6KW | L22: =VLOOKUP(C22,设备卡片列表!A:I,6,FALSE) -> 2020-06-08 | M22: 2020 | O22: 王林华 | P22: A | Q22: CTI | R22: 现场 | S22: 一年 | T22: 46148 | U22: 46148 | V22: =U22+364 -> 46512 | W22: =U22+183 -> 46331 | X22: CSY-01
A23: SHAED-C | B23: SHAED-C020 | C23: TTE20192944 | D23: 温湿度环境箱-Pro | E23: 54260024360140 | F23: Temperature and humidity chamber (pro) | G23: 伟思富奇（太仓） | H23: C7-1500E series pro | I23: W1090 x D1430 x H950mm=1500L | J23: 温度：-70~+180 °C；湿度：15% ~98 % RH（+ 10 ~ + 95 °C）; Pro VW 80000-K15 设备下层有水槽，可蒸汽加热 耐功耗：2kw | K23: 29A，15.6KW | L23: =VLOOKUP(C23,设备卡片列表!A:I,6,FALSE) -> 2019-11-05 | M23: 2019 | O23: 王林华 | P23: A | Q23: CTI | R23: 现场 | S23: 一年 | T23: 45943 | U23: 45940 | V23: =U23+364 -> 46304 | W23: =U23+183 -> 46123 | X23: CSY-02
A24: SHAED-C | B24: SHAED-C021 | C24: TTE20193354 | D24: 温湿度环境箱 | E24: 19110202 | F24: Temperature and humidity chamber | G24: 帕捷Partner | H24: PHV1720-DU-0404 | I24: W2000 x D1000 x H1000mm=2000L | J24: 温度范围：-70~+150℃ 温度均匀度：≤2℃ 温度偏差：≤±2℃ 温度波动度：≤1℃ 湿度范围：20~98%R.H 湿度偏差：-3%~+2%RH（>75%RH),±5%RH（≤75%RH) 升温速率：全程平均2℃/min（50kg铝锭，-40~120℃，出风口检测） 降温速率：全程平均2℃/min（50kg铝锭，+120~-40℃，出风口检测） | K24: 38A，18KW | L24: =VLOOKUP(C24,设备卡片列表!A:I,6,FALSE) -> 2020-06-15 | M24: 2020 | P24: A | Q24: CTI | R24: 现场 | S24: 一年 | T24: 46126 | U24: 46115 | V24: =U24+364 -> 46479 | W24: =U24+183 -> 46298 | X24: CSY-05
A25: SHAED-C | B25: SHAED-C022 | C25: TTE20202358 | D25: 温湿度环境箱-Pro | E25: 54260028530020 | F25: Temperature and humidity chamber (pro) | G25: 伟思富奇（太仓） | H25: C7-1500E series pro | I25: W1090 x D1430 x H950mm=1500L | J25: 温度：-70~+180 °C；湿度：15% ~98 % RH（+ 10 ~ + 95 °C） 升降温速率：±2℃/min Pro 耐功耗：2kw | K25: 29A，15.6KW | L25: =VLOOKUP(C25,设备卡片列表!A:I,6,FALSE) -> 2020-10-20 | M25: 2020 | O25: 王林华 | P25: A | Q25: CTI | R25: 现场 | S25: 一年 | T25: 46244 | U25: 46241 | V25: =U25+364 -> 46605 | W25: =U25+183 -> 46424 | X25: CSY-02
A26: SHAED-C | B26: SHAED-C023 | C26: TTE20202357 | D26: 温湿度环境箱 | E26: 54260028530010 | F26: Temperature and humidity chamber | G26: 伟思富奇（太仓） | H26: C7-1500E series | I26: W1090 x D1430 x H950mm=1500L | J26: 温度：-70~+150 °C；湿度：15% ~98 % RH（+ 10 ~ + 95 °C） 升降温速率：±2℃/min 耐功耗：2kw | K26: 29A，15.6KW | L26: =VLOOKUP(C26,设备卡片列表!A:I,6,FALSE) -> 2020-10-20 | M26: 2020 | O26: 王林华 | P26: A | Q26: CTI | R26: 现场 | S26: 一年 | T26: 46244 | U26: 46241 | V26: =U26+364 -> 46605 | W26: =U26+183 -> 46424 | X26: CSY-01
A27: SHAED-C | B27: SHAED-C024 | C27: TTF20200842 | D27: 高低温试验箱 | E27: GDW200531014 | F27: Temperature and humidity chamber | G27: 上海苏盈 | H27: GDJ-1600C | I27: W1090 x D1430 x H950mm=1500L | J27: 温度：-70~+150 °C 升降温速率：±2℃/min | K27: 15KW | L27: =VLOOKUP(C27,设备卡片列表!A:I,6,FALSE) -> 2020-07-28 | M27: 2020 | N27: 恒西路 | O27: 韩琦浩 | P27: A | Q27: CTI | R27: 现场 | S27: 一年 | T27: 46244 | U27: 46244 | V27: =U27+364 -> 46608 | W27: =U27+183 -> 46427 | X27: CSY-07
A28: SHAED-C | B28: SHAED-C025 | C28: TTE20202878 | D28: 环境箱-匹配振动台 | E28: 201260 | F28: Temperature chamber (for vibration equipment) | G28: 重庆阿泰可 | H28: CH1500TCVT（垂直） | I28: W1200 x D1100 x H1160mm=1531L | J28: 与SHAED-V0026匹配 温度：-70~+150 °C 温度偏差：≤±2℃ 温度波动度：≤±0.5℃ 温度均匀度：≤±2℃ 温度变化速率：≥2℃/min | K28: 40A，22KW | L28: =VLOOKUP(C28,设备卡片列表!A:I,6,FALSE) -> 2020-12-01 | M28: 2020 | O28: 张杰 | P28: A | Q28: CTI | R28: 现场 | S28: 一年 | T28: 46244 | U28: 46241 | V28: =U28+364 -> 46605 | W28: =U28+183 -> 46424 | X28: CSY-03
A29: SHAED-C | B29: SHAED-C026 | C29: TTE20210727 | D29: 快速温度变化试验箱-匹配振动台 | E29: 201398 | F29: Rapid temperature change with humidity chamber (for vibration equipment) | G29: 重庆阿泰可 | H29: CH700CVTH-10ESS（垂直+水平） | I29: W800 x D900 x H900mm=650L | J29: 与SHAED-V0036匹配 温度：-70~+200 °C 温度偏差：≤±2℃ 温度波动度：≤±0.5℃ 温度均匀度：≤±2℃ 温度变化速率：10℃/min | K29: 88A，55KW | L29: =VLOOKUP(C29,设备卡片列表!A:I,6,FALSE) -> 2021-04-28 | M29: 2021 | O29: 张杰 | P29: A | Q29: CTI | R29: 现场 | S29: 一年 | T29: 45979 | U29: 45978 | V29: =U29+364 -> 46342 | W29: =U29+183 -> 46161 | X29: CSY-04
A30: SHAED-C | B30: SHAED-C027 | C30: TTE20210968 | D30: 温湿度环境箱 | E30: 54260030750030 | F30: Temperature and humidity chamber | G30: 伟思富奇（太仓） | H30: C4-340E series | I30: W580 x D760 x H750mm=340L | J30: 温度：-40~+150 °C；湿度：15% ~98 % RH（+ 10 ~ + 95 °C） 升降温速率：±2℃/min 耐功耗：2kw | K30: 15.3A，6.5KW | L30: =VLOOKUP(C30,设备卡片列表!A:I,6,FALSE) -> 2021-06-03 | M30: 2021 | P30: A | Q30: CTI | R30: 现场 | S30: 一年 | T30: 46076 | U30: 46064 | V30: =U30+364 -> 46428 | W30: =U30+183 -> 46247 | X30: CSY-06
A31: SHAED-C | B31: SHAED-C028 | C31: TTE20210969 | D31: 温湿度环境箱 | E31: 54260030750040 | F31: Temperature and humidity chamber | G31: 伟思富奇（太仓） | H31: C4-340E series | I31: W580 x D760 x H750mm=340L | J31: 温度：-40~+150 °C；湿度：15% ~98 % RH（+ 10 ~ + 95 °C） 升降温速率：±2℃/min 耐功耗：2kw | K31: 15.3A，6.5KW | L31: =VLOOKUP(C31,设备卡片列表!A:I,6,FALSE) -> 2021-06-03 | M31: 2021 | P31: A | Q31: CTI | R31: 现场 | S31: 一年 | T31: 46076 | U31: 46064 | V31: =U31+364 -> 46428 | W31: =U31+183 -> 46247 | X31: CSY-06
A32: SHAED-C | B32: SHAED-C029 | C32: TTE20210970 | D32: 温湿度环境箱 | E32: 54260030750060 | F32: Temperature and humidity chamber | G32: 伟思富奇（太仓） | H32: C4-340E series | I32: W580 x D760 x H750mm=340L | J32: 温度：-40~+150 °C；湿度：15% ~98 % RH（+ 10 ~ + 95 °C） 升降温速率：±2℃/min 耐功耗：2kw | K32: 15.3A，6.5KW | L32: =VLOOKUP(C32,设备卡片列表!A:I,6,FALSE) -> 2021-06-03 | M32: 2021 | P32: A | Q32: CTI | R32: 现场 | S32: 一年 | T32: 46076 | U32: 46064 | V32: =U32+364 -> 46428 | W32: =U32+183 -> 46247 | X32: CSY-06
A33: SHAED-C | B33: SHAED-C030 | C33: TTE20210971 | D33: 温湿度环境箱 | E33: 54260030750050 | F33: Temperature and humidity chamber | G33: 伟思富奇（太仓） | H33: C4-340E series | I33: W580 x D760 x H750mm=340L | J33: 温度：-40~+150 °C；湿度：15% ~98 % RH（+ 10 ~ + 95 °C） 升降温速率：±2℃/min 耐功耗：2kw | K33: 15.3A，6.5KW | L33: =VLOOKUP(C33,设备卡片列表!A:I,6,FALSE) -> 2021-06-03 | M33: 2021 | P33: A | Q33: CTI | R33: 现场 | S33: 一年 | T33: 46076 | U33: 46064 | V33: =U33+364 -> 46428 | W33: =U33+183 -> 46247 | X33: CSY-06
A34: SHAED-C | B34: SHAED-C031 | C34: TTE20212750 | D34: 温湿度环境箱-Pro | E34: 54260032230010 | F34: Temperature and humidity chamber (pro) | G34: 伟思富奇（太仓） | H34: C7-1000E series pro | I34: W1090 x D900 x H950mm=1000L | J34: 温度：-70~+180 °C；湿度：15% ~98 % RH（+ 10 ~ + 95 °C） 升降温速率：±2℃/min Pro 耐功耗：2kw | K34: 25A，14KW | L34: =VLOOKUP(C34,设备卡片列表!A:I,6,FALSE) -> 2021-11-10 | M34: 2021 | P34: A | Q34: CTI | R34: 现场 | S34: 一年 | T34: 46244 | U34: 46241 | V34: =U34+364 -> 46605 | W34: =U34+183 -> 46424 | X34: CSY-02
A35: SHAED-C | B35: SHAED-C032 | C35: TTE20213033 | D35: 温湿度环境箱 | E35: 21092304 | F35: Temperature and humidity chamber | G35: 帕捷Partner | H35: PMH7010-D | I35: W500 x D400 x H600mm=120L | J35: 温度范围：-70~+150℃ 温度均匀度：≤2℃ 温度偏差：≤±2℃ 温度波动度：≤1℃ 湿度范围：20~98%R.H 湿度偏差：-3%~+2%RH（>75%RH),±5%RH（≤75%RH) 升温速率：全程平均2℃/min（50kg铝锭，-40~120℃，出风口检测） 降温速率：全程平均2℃/min（50kg铝锭，+120~-40℃，出风口检测） | K35: 16A，5KW | L35: =VLOOKUP(C35,设备卡片列表!A:I,6,FALSE) -> 2021-11-08 | M35: 2021 | P35: A | Q35: CTI | R35: 现场 | S35: 一年 | T35: 45531 | U35: 2024/8/22 转非金属材料 | V35: =U35+364 -> #VALUE! | W35: =U35+183 -> #VALUE! | X35: CSY-05 | Y35: 转非金属材料 | Z35: 转非金属材料 | AA35: 转非金属材料
A36: SHAED-C | B36: SHAED-C033 | C36: TTE20213034 | D36: 温湿度环境箱 | E36: 21092305 | F36: Temperature and humidity chamber | G36: 帕捷Partner | H36: PMH7010-D | I36: W500 x D400 x H600mm=120L | J36: 温度范围：-70~+150℃ 温度均匀度：≤2℃ 温度偏差：≤±2℃ 温度波动度：≤1℃ 湿度范围：20~98%R.H 湿度偏差：-3%~+2%RH（>75%RH),±5%RH（≤75%RH) 升温速率：全程平均2℃/min（50kg铝锭，-40~120℃，出风口检测） 降温速率：全程平均2℃/min（50kg铝锭，+120~-40℃，出风口检测） | K36: 16A，5KW | L36: =VLOOKUP(C36,设备卡片列表!A:I,6,FALSE) -> 2021-10-22 | M36: 2021 | P36: A | Q36: CTI | R36: 现场 | S36: 一年 | T36: 45531 | U36: 2024/8/22 转非金属材料 | V36: =U36+364 -> #VALUE! | W36: =U36+183 -> #VALUE! | X36: CSY-05 | Y36: 转非金属材料 | Z36: 转非金属材料 | AA36: 转非金属材料
A37: SHAED-C | B37: SHAED-C034 | C37: TTE20222887 | D37: 温湿度环境箱 | E37: 54260035250010 | F37: Temperature and humidity chamber | G37: 伟思富奇（太仓） | H37: C4-340E series | I37: W580 x D760 x H750mm=340L | J37: 温度：-40~+150 °C；湿度：15% ~98 % RH（+ 10 ~ + 95 °C） 升降温速率：±2℃/min 耐功耗：2kw | K37: 15.3A，6.5KW | L37: 44742 | M37: 2022 | P37: A | Q37: CTI | R37: 现场 | S37: 一年 | T37: 46164 | U37: 46148 | V37: =U37+364 -> 46512 | W37: =U37+183 -> 46331 | X37: CSY-06
A38: SHAED-C | B38: SHAED-C035 | C38: TTE20222888 | D38: 温湿度环境箱 | E38: 54260035250020 | F38: Temperature and humidity chamber | G38: 伟思富奇（太仓） | H38: C4-340E series | I38: W580 x D760 x H750mm=340L | J38: 温度：-40~+150 °C；湿度：15% ~98 % RH（+ 10 ~ + 95 °C） 升降温速率：±2℃/min 耐功耗：2kw | K38: 15.3A，6.5KW | L38: 44749 | M38: 2022 | P38: A | Q38: CTI | R38: 现场 | S38: 一年 | T38: 46183 | U38: 46182 | V38: =U38+364 -> 46546 | W38: =U38+183 -> 46365 | X38: CSY-06
A39: SHAED-C | B39: SHAED-C036 | C39: TTE20222889 | D39: 温湿度环境箱 | E39: 54260035250030 | F39: Temperature and humidity chamber | G39: 伟思富奇（太仓） | H39: C4-340E series | I39: W580 x D760 x H750mm=340L | J39: 温度：-40~+150 °C；湿度：15% ~98 % RH（+ 10 ~ + 95 °C） 升降温速率：±2℃/min 耐功耗：2kw | K39: 15.3A，6.5KW | L39: 44749 | M39: 2022 | P39: A | Q39: CTI | R39: 现场 | S39: 一年 | T39: 46183 | U39: 46182 | V39: =U39+364 -> 46546 | W39: =U39+183 -> 46365 | X39: CSY-06
A40: SHAED-C | B40: SHAED-C037 | C40: TTE20222890 | D40: 温湿度环境箱 | E40: 54260035250040 | F40: Temperature and humidity chamber | G40: 伟思富奇（太仓） | H40: C4-340E series | I40: W580 x D760 x H750mm=340L | J40: 温度：-40~+150 °C；湿度：15% ~98 % RH（+ 10 ~ + 95 °C） 升降温速率：±2℃/min 耐功耗：2kw | K40: 15.3A，6.5KW | L40: 44753 | M40: 2022 | P40: A | Q40: CTI | R40: 现场 | S40: 一年 | T40: 46183 | U40: 46182 | V40: =U40+364 -> 46546 | W40: =U40+183 -> 46365 | X40: CSY-06
...

Sheet 设备搜索
B1: 将短号填入下方搜索栏
B2: SHAED-C064
B3: 设备编号 | C3: 内部编号 | D3: 出厂编号 | E3: 设备名称 | F3: Equipment | G3: 制造厂商 | H3: 型号 | I3: 设备尺寸 | J3: 主要参数 | K3: 能耗 | L3: 投入使用时间 | M3: 到货日期 | N3: 放置地点 | O3: 负责人 | P3: 授权设备分类 | Q3: 校准机构 | R3: 校准有效期 | S3: 校准 地点 | T3: 上次校准有效期 | U3: 校准时间 | V3: 计划校准时间 | W3: 期间核查 | X3: 溯源计划 | Y3: 校准计划 | Z3: 校准状态 | AA3: 备注 | AB3: 与校准确定好时间 标记在预定表上 | AC3: 当天实际校准好 | AD3: 拿到没问题报告 | AE3: 校准确认好
B4: {=_xlfn._xlws.FILTER(设备清单!B2:AA2181,LEFT(设备清单!B2:B2181,LEN(B2))=B2,"none")} -> SHAED-C064 | C4: TTE20231179 | D4: 温湿度环境箱-匹配振动台 | E4: 22-1081 | F4: Temperature and humidity chamber (for vibration Equipment) | G4: 宏瑞达 | H4: HTHV3500-40W | I4: 3500L | J4: 与SHAED-V063匹配 温度：-40~+150 °C 温度偏差：≤±2℃ 温度波动度：≤±0.5℃ 升温速率：线性 ＞1℃/min（带载200kg铝，-40~120℃） 降温速率：平均＞1℃/min（带载200kg铝，+85~-40℃） 温度均匀度：≤±2℃ 湿度：20% ~98 % RH（+ 20 ~ + 85 °C） | K4: 60A，24KW | L4: 45017 | M4: 2023 | N4: 0 | O4: 张杰 | P4: A | Q4: CTI | R4: 现场 | S4: 一年 | T4: 46076 | U4: 46065 | V4: 46429 | W4: 46248 | X4: CSY-08 | Y4: 0 | Z4: 0 | AA4: 0

Sheet 报告填入专用
B1: 设备名称 | C1: 型号 | D1: 设备编号 | E1: 有效期 | G1: 把设备编号复制在下列蓝色区域
A2: 要中文 | B2: =VLOOKUP(G2,设备清单!B:V,3,0) -> 机械振动台 水平 1200mm C064 有湿度 3500L | C2: =VLOOKUP(G2,设备清单!B:V,7,0) -> ES-80LS3-445 | D2: =VLOOKUP(G2,设备清单!B:V,1,0) -> SHAED-V063 | E2: =VLOOKUP(G2,设备清单!B:V,21,0) -> 46427 | G2: SHAED-V063 | I2: 中西结合疗效好 | J2: =B2&B13 -> 机械振动台 水平 1200mm C064 有湿度 3500LMechanical vibrator machine | K2: =VLOOKUP(G2,设备清单!B:V,7,0) -> ES-80LS3-445 | L2: =VLOOKUP(G2,设备清单!B:V,1,0) -> SHAED-V063 | M2: =VLOOKUP(G2,设备清单!B:V,21,0) -> 46427
B3: =VLOOKUP(G3,设备清单!B:V,3,0) -> 可编程直流电源 | C3: =VLOOKUP(G3,设备清单!B:V,7,0) -> PBZ20-20 | D3: =VLOOKUP(G3,设备清单!B:V,1,0) -> SHAED-P001 | E3: =VLOOKUP(G3,设备清单!B:V,21,0) -> 46548 | G3: SHAED-P001 | J3: =B3&B14 -> 可编程直流电源Programmable DC power supply | K3: =VLOOKUP(G3,设备清单!B:V,7,0) -> PBZ20-20 | L3: =VLOOKUP(G3,设备清单!B:V,1,0) -> SHAED-P001 | M3: =VLOOKUP(G3,设备清单!B:V,21,0) -> 46548
B4: =VLOOKUP(G4,设备清单!B:V,3,0) -> 可编程直流电源 | C4: =VLOOKUP(G4,设备清单!B:V,7,0) -> PBZ20-20 | D4: =VLOOKUP(G4,设备清单!B:V,1,0) -> SHAED-P001 | E4: =VLOOKUP(G4,设备清单!B:V,21,0) -> 46548 | G4: SHAED-P001 | J4: =B4&B15 -> 可编程直流电源Programmable DC power supply | K4: =VLOOKUP(G4,设备清单!B:V,7,0) -> PBZ20-20 | L4: =VLOOKUP(G4,设备清单!B:V,1,0) -> SHAED-P001 | M4: =VLOOKUP(G4,设备清单!B:V,21,0) -> 46548
B5: =VLOOKUP(G5,设备清单!B:V,3,0) -> 可编程直流电源 | C5: =VLOOKUP(G5,设备清单!B:V,7,0) -> PBZ20-20 | D5: =VLOOKUP(G5,设备清单!B:V,1,0) -> SHAED-P001 | E5: =VLOOKUP(G5,设备清单!B:V,21,0) -> 46548 | G5: SHAED-P001 | J5: =B5&B16 -> 可编程直流电源Programmable DC power supply | K5: =VLOOKUP(G5,设备清单!B:V,7,0) -> PBZ20-20 | L5: =VLOOKUP(G5,设备清单!B:V,1,0) -> SHAED-P001 | M5: =VLOOKUP(G5,设备清单!B:V,21,0) -> 46548
B6: =VLOOKUP(G6,设备清单!B:V,3,0) -> 可编程直流电源 | C6: =VLOOKUP(G6,设备清单!B:V,7,0) -> PBZ20-20 | D6: =VLOOKUP(G6,设备清单!B:V,1,0) -> SHAED-P001 | E6: =VLOOKUP(G6,设备清单!B:V,21,0) -> 46548 | G6: SHAED-P001 | J6: =B6&B17 -> 可编程直流电源Programmable DC power supply | K6: =VLOOKUP(G6,设备清单!B:V,7,0) -> PBZ20-20 | L6: =VLOOKUP(G6,设备清单!B:V,1,0) -> SHAED-P001 | M6: =VLOOKUP(G6,设备清单!B:V,21,0) -> 46548
B7: =VLOOKUP(G7,设备清单!B:V,3,0) -> 可编程直流电源 | C7: =VLOOKUP(G7,设备清单!B:V,7,0) -> PBZ20-20 | D7: =VLOOKUP(G7,设备清单!B:V,1,0) -> SHAED-P001 | E7: =VLOOKUP(G7,设备清单!B:V,21,0) -> 46548 | G7: SHAED-P001 | J7: =B7&B18 -> 可编程直流电源Programmable DC power supply | K7: =VLOOKUP(G7,设备清单!B:V,7,0) -> PBZ20-20 | L7: =VLOOKUP(G7,设备清单!B:V,1,0) -> SHAED-P001 | M7: =VLOOKUP(G7,设备清单!B:V,21,0) -> 46548
B8: =VLOOKUP(G8,设备清单!B:V,3,0) -> 可编程直流电源 | C8: =VLOOKUP(G8,设备清单!B:V,7,0) -> PBZ20-20 | D8: =VLOOKUP(G8,设备清单!B:V,1,0) -> SHAED-P001 | E8: =VLOOKUP(G8,设备清单!B:V,21,0) -> 46548 | G8: SHAED-P001 | J8: =B8&B19 -> 可编程直流电源Programmable DC power supply | K8: =VLOOKUP(G8,设备清单!B:V,7,0) -> PBZ20-20 | L8: =VLOOKUP(G8,设备清单!B:V,1,0) -> SHAED-P001 | M8: =VLOOKUP(G8,设备清单!B:V,21,0) -> 46548
B9: =VLOOKUP(G9,设备清单!B:V,3,0) -> 可编程直流电源 | C9: =VLOOKUP(G9,设备清单!B:V,7,0) -> PBZ20-20 | D9: =VLOOKUP(G9,设备清单!B:V,1,0) -> SHAED-P001 | E9: =VLOOKUP(G9,设备清单!B:V,21,0) -> 46548 | G9: SHAED-P001 | J9: =B9&B20 -> 可编程直流电源Programmable DC power supply | K9: =VLOOKUP(G9,设备清单!B:V,7,0) -> PBZ20-20 | L9: =VLOOKUP(G9,设备清单!B:V,1,0) -> SHAED-P001 | M9: =VLOOKUP(G9,设备清单!B:V,21,0) -> 46548
B10: =VLOOKUP(G10,设备清单!B:V,3,0) -> 可编程直流电源 | C10: =VLOOKUP(G10,设备清单!B:V,7,0) -> PBZ20-20 | D10: =VLOOKUP(G10,设备清单!B:V,1,0) -> SHAED-P001 | E10: =VLOOKUP(G10,设备清单!B:V,21,0) -> 46548 | G10: SHAED-P001 | J10: =B10&B21 -> 可编程直流电源Programmable DC power supply | K10: =VLOOKUP(G10,设备清单!B:V,7,0) -> PBZ20-20 | L10: =VLOOKUP(G10,设备清单!B:V,1,0) -> SHAED-P001 | M10: =VLOOKUP(G10,设备清单!B:V,21,0) -> 46548
B11: =VLOOKUP(G11,设备清单!B:V,3,0) -> 可编程直流电源 | C11: =VLOOKUP(G11,设备清单!B:V,7,0) -> PBZ20-20 | D11: =VLOOKUP(G11,设备清单!B:V,1,0) -> SHAED-P001 | E11: =VLOOKUP(G11,设备清单!B:V,21,0) -> 46548 | G11: SHAED-P001 | J11: =B11&B22 -> 可编程直流电源Programmable DC power supply | K11: =VLOOKUP(G11,设备清单!B:V,7,0) -> PBZ20-20 | L11: =VLOOKUP(G11,设备清单!B:V,1,0) -> SHAED-P001 | M11: =VLOOKUP(G11,设备清单!B:V,21,0) -> 46548
A13: 要洋文 | B13: =VLOOKUP(G2,设备清单!B:V,5,0) -> Mechanical vibrator machine | C13: =VLOOKUP(G2,设备清单!B:V,7,0) -> ES-80LS3-445 | D13: =VLOOKUP(G2,设备清单!B:V,1,0) -> SHAED-V063 | E13: =VLOOKUP(G2,设备清单!B:V,21,0) -> 46427
B14: =VLOOKUP(G3,设备清单!B:V,5,0) -> Programmable DC power supply | C14: =VLOOKUP(G3,设备清单!B:V,7,0) -> PBZ20-20 | D14: =VLOOKUP(G3,设备清单!B:V,1,0) -> SHAED-P001 | E14: =VLOOKUP(G3,设备清单!B:V,21,0) -> 46548
B15: =VLOOKUP(G4,设备清单!B:V,5,0) -> Programmable DC power supply | C15: =VLOOKUP(G4,设备清单!B:V,7,0) -> PBZ20-20 | D15: =VLOOKUP(G4,设备清单!B:V,1,0) -> SHAED-P001 | E15: =VLOOKUP(G4,设备清单!B:V,21,0) -> 46548
B16: =VLOOKUP(G5,设备清单!B:V,5,0) -> Programmable DC power supply | C16: =VLOOKUP(G5,设备清单!B:V,7,0) -> PBZ20-20 | D16: =VLOOKUP(G5,设备清单!B:V,1,0) -> SHAED-P001 | E16: =VLOOKUP(G5,设备清单!B:V,21,0) -> 46548
B17: =VLOOKUP(G6,设备清单!B:V,5,0) -> Programmable DC power supply | C17: =VLOOKUP(G6,设备清单!B:V,7,0) -> PBZ20-20 | D17: =VLOOKUP(G6,设备清单!B:V,1,0) -> SHAED-P001 | E17: =VLOOKUP(G6,设备清单!B:V,21,0) -> 46548
B18: =VLOOKUP(G7,设备清单!B:V,5,0) -> Programmable DC power supply | C18: =VLOOKUP(G7,设备清单!B:V,7,0) -> PBZ20-20 | D18: =VLOOKUP(G7,设备清单!B:V,1,0) -> SHAED-P001 | E18: =VLOOKUP(G7,设备清单!B:V,21,0) -> 46548
B19: =VLOOKUP(G8,设备清单!B:V,5,0) -> Programmable DC power supply | C19: =VLOOKUP(G8,设备清单!B:V,7,0) -> PBZ20-20 | D19: =VLOOKUP(G8,设备清单!B:V,1,0) -> SHAED-P001 | E19: =VLOOKUP(G8,设备清单!B:V,21,0) -> 46548
B20: =VLOOKUP(G9,设备清单!B:V,5,0) -> Programmable DC power supply | C20: =VLOOKUP(G9,设备清单!B:V,7,0) -> PBZ20-20 | D20: =VLOOKUP(G9,设备清单!B:V,1,0) -> SHAED-P001 | E20: =VLOOKUP(G9,设备清单!B:V,21,0) -> 46548
B21: =VLOOKUP(G10,设备清单!B:V,5,0) -> Programmable DC power supply | C21: =VLOOKUP(G10,设备清单!B:V,7,0) -> PBZ20-20 | D21: =VLOOKUP(G10,设备清单!B:V,1,0) -> SHAED-P001 | E21: =VLOOKUP(G10,设备清单!B:V,21,0) -> 46548
B22: =VLOOKUP(G11,设备清单!B:V,5,0) -> Programmable DC power supply | C22: =VLOOKUP(G11,设备清单!B:V,7,0) -> PBZ20-20 | D22: =VLOOKUP(G11,设备清单!B:V,1,0) -> SHAED-P001 | E22: =VLOOKUP(G11,设备清单!B:V,21,0) -> 46548

Sheet 设备卡片列表
A1: 设备卡片列表
A2: 设备编号 | B2: 设备名称 | C2: 型号规格 | D2: 出厂编号 | E2: ABCD分类 | F2: 投用日期 | G2: 制造厂 | H2: 供货商 | I2: 采购原值（含税）
A3: ATTEVLSH00054-1 | B3: 插拔力试验机 | C3: 1220S | D3: 122300A8105 | E3: A类 | F3: 2008-01-29 | G3: 台湾顺滢 | H3: 台湾顺滢
A4: ATTEVLSH00067 | B4: 淋雨试验箱 | C4: LX-1000 | D4: G70082 | E4: A类 | F4: 2008-03-01 | G4: 无锡南亚 | H4: 无锡市南亚试验设备有限公司
A5: TTE20131825 | B5: 直流电子负载 | C5: IT8512C | D5: / | E5: C类 | F5: 2013-10-25 | G5: 美国艾德克斯ITECH | H5: 上海振莺机电设备有限公司 | I5: 3950
A6: TTE20132028 | B6: 示波器 | C6: DPO3054 | D6: C027260 | E6: A类 | F6: 2013-11-28 | G6: 美国泰克Tek | H6: 上海振莺机电设备有限公司 | I6: 66000
A7: TTE20132275 | B7: 万用表 | C7: 30M（六位半） | D7: XI0538 | E7: B类 | F7: 2013-12-19 | G7: 德国高美GMC | H7: 上海振莺机电设备有限公司 | I7: 16000
A8: TTE20140102 | B8: IPX9K高压清洗试验装置 | C8: IPX9K | D8: / | E8: A类 | F8: 2014-01-28 | G8: 上海春风 | H8: 上海春风实业有限公司 | I8: 86000
A9: TTE20143011 | B9: 振动试验机 | C9: DC-1000-15 | D9: 130933 | E9: A类 | F9: 2013-09-10 | G9: 苏州苏试 | H9: 苏州苏试试验仪器股份有限公司 | I9: 233000
A10: TTE20150409 | B10: IP防水试验机 | C10: KXT1302 | D10: / | E10: B类 | F10: 2015-04-20 | G10: 东莞科翔 | H10: 东莞市科翔试验设备有限公司 | I10: 42000
A11: TTE20150909 | B11: JIS防水试验装置 | C11: TMJ-9710A | D11: T-10A-150331001 | E11: A类 | F11: 2015-05-15 | G11: 台湾铁木真科技 | H11: 铁木真电子科技（昆山）有限公司 | I11: 115000
A12: TTE20150911 | B12: 两厢式冰水冲击试验箱 | C12: KTCE-018TBS | D12: 20150325 | E12: A类 | F12: 2015-07-14 | G12: 上海庆生 | H12: 上海庆生测试设备有限公司 | I12: 438000
A13: TTE20151930 | B13: 机械冲击碰撞试验台 | C13: SY11-200 | D13: J150432 | E13: A类 | F13: 2015-05-27 | G13: 苏州东菱振动 | H13: 苏州东菱振动试验仪器有限公司
A14: TTE20160719 | B14: 可编程直流电源 | C14: PBZ20-20 | D14: WA002723 | E14: A类 | F14: 2016-04-15 | G14: 日本菊水KIKUSUI | H14: 科电贸易(上海)有限公司 | I14: 57450
A15: TTE20165250 | B15: 可编程直流电源 | C15: PBZ20-20 | D15: WB001609 | E15: A类 | F15: 2016-11-30 | G15: 日本菊水KIKUSUI | H15: 科电贸易（上海）有限公司 | I15: 58700
A16: TTE20165251 | B16: 可编程直流电源 | C16: PBZ20-20 | D16: WC002180 | E16: A类 | F16: 2016-11-30 | G16: 日本菊水KIKUSUI | H16: 科电贸易（上海）有限公司 | I16: 58700
A17: TTE20175957 | B17: 电子负载 | C17: IT8812 | D17: 600223011727430003 | E17: C类 | F17: 2017-10-31 | G17: 美国艾德克斯ITECH | H17: 深圳市科瑞杰科技有限公司 | I17: 4180
A18: TTE20176501 | B18: 电子负载 | C18: IT8211 | D18: 600109010727610010 | E18: D类 | F18: 2017-11-23 | G18: 美国艾德克斯ITECH | H18: 上海振莺机电设备有限公司 | I18: 1200
A19: TTE20176502 | B19: 电子负载 | C19: IT8211 | D19: 600109010727610011 | E19: D类 | F19: 2017-11-23 | G19: 美国艾德克斯ITECH | H19: 上海振莺机电设备有限公司 | I19: 1200
A20: TTE20181799 | B20: 防尘试验机 | C20: KTM-DT90F | D20: T1640 | E20: A类 | F20: 2018-06-06 | G20: 台湾铁木真科技 | H20: 铁木真电子科技（昆山）有限公司 | I20: 185000
A21: TTE20189476 | B21: 振动试验机 | C21: M437A | D21: SH1801019 | E21: A类 | F21: 2018-07-31 | G21: 北京航天希尔 | H21: 北京航天希尔测试技术有限公司 | I21: 435000
A22: TTE20190182 | B22: 瞬间断线测试仪 | C22: NMS 10 | D22: S18110155 | E22: A类 | F22: 2019-01-28 | G22: 日本耐苛（NAC) | H22: 上海振莺机电设备有限公司 | I22: 94000
A23: TTE20190183 | B23: 电流钳 | C23: E3N/（0-100）A | D23: No196365RMH | E23: C类 | F23: 2019-03-18 | G23: CA/chauvin-arnoux | H23: 上海振莺机电设备有限公司 | I23: 4500
A24: TTE20190184 | B24: 电流钳 | C24: E3N/（0-100）A | D24: No164588RJH | E24: C类 | F24: 2019-02-13 | G24: CA/chauvin-arnoux | H24: 上海振莺机电设备有限公司 | I24: 4500
A25: TTE20191908 | B25: 七位半万用表 | C25: 34470A | D25: MY59002111 | E25: B类 | F25: 2019-07-24 | G25: 美国是德Keysight | H25: 深圳市新高电子有限公司 | I25: 20900
... A191: TTE20213765 | B191: 示波记录仪 | C191: DL850E-H（HC/M1/HD1/P4） | D191: 90XA21879 | E191: A类 | F191: 2021-12-06 | G191: 日本横河日本横河Yokogawa | H191: 上海成测实业有限公司 | I191: 199000
A192: TTF20110527 | B192: 加速规 | C192: CA-YD-107 | D192: / | E192: B类 | F192: 2012-07-05 | G192: 苏州苏试 | H192: 苏州苏试试验仪器有限公司
A193: TTF20110528 | B193: 加速规 | C193: CA-YD-107 | D193: / | E193: B类 | F193: 2012-07-05 | G193: 苏州苏试 | H193: 苏州苏试试验仪器有限公司
A194: TTF20110529 | B194: 加速规 | C194: CA-YD-107 | D194: / | E194: B类 | F194: 2012-07-05 | G194: 苏州苏试 | H194: 苏州苏试试验仪器有限公司
A195: TTF20110530 | B195: 加速规 | C195: CA-YD-107 | D195: / | E195: B类 | F195: 2012-07-05 | G195: 苏州苏试 | H195: 苏州苏试试验仪器有限公司
A196: TTF20110531 | B196: 加速规 | C196: CA-YD-107 | D196: / | E196: B类 | F196: 2012-07-05 | G196: 苏州苏试 | H196: 苏州苏试试验仪器有限公司
A197: TTF20140003 | B197: 直流稳压电源 | C197: PBZ40-10 | D197: TM001786 | E197: A类 | F197: 2014-03-12 | G197: 日本菊水KIKUSUI | H197: 科电贸易(上海)有限公司 | I197: 62700
A198: TTF20170477 | B198: 直流电源 | C198: PAV36-12 | D198: XH002048 | E198: B类 | F198: 2017-10-19 | G198: 日本菊水KIKUSUI | H198: 科电贸易（上海）有限公司 | I198: 10940
A199: TTF20170478 | B199: 直流电源 | C199: PAV36-12 | D199: XH002047 | E199: B类 | F199: 2017-10-19 | G199: 日本菊水KIKUSUI | H199: 科电贸易（上海）有限公司 | I199: 10940
A200: TTF20170479 | B200: 直流电源 | C200: PAV36-12 | D200: XH002046 | E200: B类 | F200: 2017-10-19 | G200: 日本菊水KIKUSUI | H200: 科电贸易（上海）有限公司 | I200: 10940
A201: TTF20170480 | B201: 直流电源 | C201: PAV650-1 | D201: XL001771 | E201: B类 | F201: 2017-12-11 | G201: 日本菊水KIKUSUI | H201: 科电贸易（上海）有限公司 | I201: 16410
A202: TTF20170481 | B202: 直流电源 | C202: PAV650-1 | D202: XL001772 | E202: B类 | F202: 2017-12-11 | G202: 日本菊水KIKUSUI | H202: 科电贸易（上海）有限公司 | I202: 16410
A203: TTF20180042 | B203: 振动控制器 | C203: RHC-920-2 | D203: 1073916 | E203: B类 | F203: 2018-01-24 | G203: 上海瑞鸿信息科技有限公 司 | H203: 上海瑞鸿信息科技有限公司 | I203: 49000
A204: TTF20190020 | B204: 工业除湿机 | C204: ST-8156C | D204: 2190827232075 | E204: C类 | F204: 2019-12-05 | G204: 上海湿腾 | H204: 上海标恒电子科技有限公司 | I204: 2850
A205: TTF20190021 | B205: 工业除湿机 | C205: ST-8156C | D205: 2190827232045 | E205: C类 | F205: 2019-12-05 | G205: 上海湿腾 | H205: 上海标恒电子科技有限公司 | I205: 2850
...

Sheet 设备布局
A1: H002
A2: 苏盈1000L PH-1000T 瞿杰
A4: H007 | E4: C021 | G4: S010 | I4: S001 | K4: S007 | M4: S004 | O4: S003 | Q4: S002 | S4: S005
A5: 苏盈1000L PH-1000 瞿杰 | E5: 帕捷2000L PHV1720-DU-0404 韩琦浩 | G5: 帕捷90L TSV12055W 韩琦浩 | I5: 广五所120L TS-120SW 李耀辉 | K5: 广五所120L TS-120SW 韩琦浩 | M5: 广五所300L TS-300SW 李耀辉 | O5: 广五所300L TS-300SW 李耀辉 | Q5: 广五所300L TS-300SW 李耀辉 | S5: 广五所1000L ETS1000-55W-D 李耀辉
A7: H006 | E7: Q005 | G7: S006 | I7: S011 | K7: Q009 | M7: Q008 | O7: Q006 | Q7: Q007 | S7: Q010 | U7: Q011 | W7: Q004 | Y7: Q003 | AA7: Q002 | AC7: Q001
A8: 苏盈100L PH-100T 瞿杰 | E8: 帕捷2000L PHR720W-20 韩琦浩 | G8: 阿泰可200L CST150-2T 韩琦浩 | I8: 帕捷90L TSV12055W 韩琦浩 | K8: 帕捷1000L PHR710W-2020 傅强 | M8: 帕捷1000L PHR710W-2020 傅强 | O8: 伟思480L C7-480/20 ESS 韩琦浩 | Q8: 伟思1300L C7-1300/20 ESS 傅强 | S8: 帕捷220L PHR702W-15 韩琦浩 | U8: 帕捷220L PHR702W-15 韩琦浩 | W8: 伟思800L C7-800/15ESS 韩琦浩 | Y8: 伟思800L C7-800/15ESS 韩琦浩 | AA8: 伟思800L C7-800/15ESS 韩琦浩 | AC8: 伟思800L C7-800/15ESS 韩琦浩
A10: H005
A11: 苏盈100L PH-100T 瞿杰 | Q11: 环境
A13: H018
A14: 阿泰可504L ADL500-T02 瞿杰
A16: H004 | E16: I002 | G16: C033 | I16: C032 | K16: S009 | M16: S008 | O16: C030 | Q16: C029 | S16: C028 | U16: C027 | W16: C011 | Y16: C010 | AA16: C002 | AC16: C004 | AE16: C003 | AG16: C001
A17: 苏盈500L PH-500T 瞿杰 | E17: JIS防水试验机 刘朝 | G17: 帕捷120L PMH7010-D 傅强 | I17: 帕捷120L PMH7010-D 傅强 | K17: 帕捷40L TSV6455A 王皓冬 | M17: 帕捷40L TSV6455A 王皓冬 | O17: 伟思340L C4-340E series 傅强 | Q17: 伟思340L C4-340E series 傅强 | S17: 伟思340L C4-340E series 傅强 | U17: 伟思340L C4-340E series 傅强 | W17: 伟思600L C7-600E 徐冬敏 | Y17: 伟思600L C7-600E 徐冬敏 | AA17: 伟思600L C7-600E 徐冬敏 | AC17: 伟思600L C7-600E 徐冬敏 | AE17: 伟思600L C7-600E 徐冬敏 | AG17: 伟思600L C7-600E 徐冬敏
A19: H003 | E19: C005 | G19: C031 | I19: C045 | K19: C044 | M19: C040 | O19: C015 | Q19: C016 | S19: C017 | U19: C018 | W19: C019 | Y19: C022 | AA19: C023 | AC19: C020
A20: 苏盈500L PH-500T 瞿杰 | E20: 伟思1000L C7-1000 pro 蒋开先 | G20: 伟思1000L C7-1000E series pro 蒋开先 | I20: 伟思1500L C7-1500E series pro 黄帅 | K20: 伟思1500L C7-1500E series pro 黄帅 | M20: 帕捷 PTV1715A-DU 蒋开先 | O20: 伟思1000L C7-1000E 蒋开先 | Q20: 伟思1000L C7-1000E 王林华 | S20: 伟思1000L C7-1000E 王林华 | U20: 伟思1000L C7-1000E 王林华 | W20: 伟思1500L C7-1500E 王林华 | Y20: 伟思1500L C7-1500E 王林华 | AA20: 伟思1500L C7-1500E 王林华 | AC20: 伟思1500L C7-1500pro K 15 王林华
A22: H008
A23: 苏盈1500L PH-1500 瞿杰
Q25: H017 | S25: H010 | U25: H009
Q26: 阿泰可504L ADL500-T02 瞿杰 | S26: 帕捷500L PTC3005-D 瞿杰 | U26: 帕捷500L PTC3005-D 瞿杰 | W26: 门
I30: H020 | U30: C055
I31: 德国宾德Binder FED720 瞿杰 | U31: 帕捷120L PMH7010-D 傅强
A33: Q015 | C33: Q017 | E33: Q019 | G33: Q020 | I33: H019 | U33: C054 | W33: S016
A34: 伟思480L C7-480/15 ESS 蒋开先 | C34: 伟思1300L C7-1300/15 ESS 王林华 | E34: 阿泰可1500L CH1500C-15ESS 王林华 | G34: 阿泰可1500L CH1500C-15ESS 王林华 | I34: 德国宾德Binder FED720 瞿杰 | U34: 帕捷120L PMH7010-D 傅强 | W34: 帕捷1000L TSH10055W 王皓冬
U36: C057
U37: 帕捷120L PMH7010-D 傅强
A39: H012 | C39: H013 | E39: S013 | G39: S015 | I39: C049 | U39: C053 | W39: C051
A40: 五和1000L GW-1000 瞿杰 | C40: 五和225L GW-225B 瞿杰 | E40: 帕捷300L TSV30055W 黄帅 | G40: 帕捷40L TSV6455A 黄帅 | I40: 帕捷2000L PHV1720W-B0505 韩琦浩 | U40: 帕捷120L PMH7010-D 王林华 | W40: 帕捷120L PMH7010-D 王林华
A42: H016 | U42: C050 | W42: C052
A43: 五和100L BGW-100B 瞿杰 | O43: 新环境 | U43: 帕捷120L PMH7010-D 王林华 | W43: 帕捷120L PMH7010-D 王林华
A45: S014 | B45: S014 | C45: Q012 | E45: Q014 | G45: C014 | I45: Q016 | K45: C013 | M45: C012
A46: 帕捷300L TSV30055W 黄帅 | C46: 伟思480L C7-480/15 ESS 蒋开先 | E46: 伟思480L C7-480/15 ESS 蒋开先 | G46: 伟思1000L C7-1000E 蒋开先 | I46: 伟思1300L C7-1300/15 ESS 王林华 | K46: 伟思1000L C7-1000E 蒋开先 | M46: 伟思1000L C7-1000E 蒋开先
A48: S012 | C48: Q013 | E48: Q018 | G48: C048 | I48: C047 | K48: C046 | M48: C058 | O48: C060 | Q48: C059 | S48: C061
A49: 伟思120L T/120/V2 黄帅 | C49: 伟思270L C7-270/15 ESS 蒋开先 | E49: 伟思270L C7-270/15 ESS 王林华 | G49: 伟思1000L C7-1000E series 黄帅 | I49: 伟思340L C7-340E series 黄帅 | K49: 伟思340L C7-340E series 黄帅 | M49: 阿泰可1500L SU1500C 傅强 | O49: 阿泰可1500L SU1500C 傅强 | Q49: 阿泰可1500L SU1500C 傅强 | S49: 阿泰可1500L SU1500C 傅强 | AI49: C039 PTV1715A-DU 黄帅
I51: C024
I52: 苏盈1500L GDJ-1600C 韩琦浩 | AK52: 电学
I55: H001 | K55: C038 | M55: C042 | O55: C041
I56: 苏盈1500L PH-1500T 瞿杰 | K56: 伟思1500L C7-1500E series 王林华 | M56: 伟思1000L C7-1000E series 黄帅 | O56: 伟思1000L C7-1000E series pro 黄帅
I58: H015 | K58: C034 | M58: C036 | O58: C037 | Q58: C035 | S58: C056
I59: 五和100L GW-100B 瞿杰 | K59: 伟思340L C4-340E series 傅强 | M59: 伟思340L C4-340E series 傅强 | O59: 伟思340L C4-340E series 傅强 | Q59: 伟思340L C4-340E series 傅强 | S59: 帕捷120L PMH7010-D 傅强
I60: H011 | S60: H014
I61: 五和1000L GW-1000B 瞿杰 | S61: 五和225L GW-225B 瞿杰
...

Sheet 大设备负责人
A1: 设备类型 | B1: 设备编号 | C1: 设备名称 | D1: 制造厂商 | E1: 型号 | F1: 设备尺寸 | G1: 负责人 | H1: 校准时间 | I1: 计划校准时间 | J1: 期间核查 | K1: 备注
A2: SHAED-C | B2: SHAED-C001 | C2: 温湿度环境箱 | D2: 伟思富奇（太仓） | E2: C7-600E series | F2: W790 x D750 x H950mm=600L | G2: 徐东敏 | H2: 44195 | I2: 44559 | J2: 44378
A3: SHAED-C | B3: SHAED-C002 | C3: 温湿度环境箱 | D3: 伟思富奇（太仓） | E3: C7-600E series | F3: W790 x D750 x H950mm=600L | G3: 徐东敏 | H3: 44153 | I3: 44517 | J3: 44336
A4: SHAED-C | B4: SHAED-C003 | C4: 温湿度环境箱 | D4: 伟思富奇（太仓） | E4: C7-600E series | F4: W790 x D750 x H950mm=600L | G4: 徐东敏 | H4: 44153 | I4: 44517 | J4: 44336
A5: SHAED-C | B5: SHAED-C004 | C5: 温湿度环境箱 | D5: 伟思富奇（太仓） | E5: C7-600E series | F5: W790 x D750 x H950mm=600L | G5: 徐东敏 | H5: 44195 | I5: 44559 | J5: 44378
A6: SHAED-C | B6: SHAED-C005 | C6: 温湿度环境箱-Pro | D6: 伟思富奇（太仓） | E6: C7-1000E seriesE Pro | F6: W1090 x D900 x H950mm=1000L | G6: 徐申扬 | H6: 44195 | I6: 44559 | J6: 44378
A7: SHAED-C | B7: SHAED-C006 | C7: 环境箱-匹配振动台 | D7: 重庆阿泰可 | E7: CH1500TCH（水平） | F7: W1200 x D1100 x H1160mm=1531L | G7: 张杰 | H7: 44195 | I7: 44559 | J7: 44378
A8: SHAED-C | B8: SHAED-C007 | C8: 环境箱-匹配振动台 | D8: 广州五所环境仪器有限公司 | E8: CT2970A2 （水平） | F8: W1500 x D1500 x H1300mm=2925L | G8: 张杰 | H8: 44161 | I8: 44525 | J8: 44344
A9: SHAED-C | B9: SHAED-C008 | C9: 环境箱-匹配振动台 | D9: 广州五所环境仪器有限公司 | E9: CT2970A2 （垂直） | F9: W1500 x D1500 x H1300mm=2925L | G9: 张杰 | H9: 44161 | I9: 44525 | J9: 44344
A10: SHAED-C | B10: SHAED-C009 | C10: 环境箱-匹配振动台 | D10: 广州五所环境仪器有限公司 | E10: CT2970A2 （垂直+水平） | F10: W1500 x D1500 x H1300mm=2925L | G10: 张杰 | H10: 44161 | I10: 44525 | J10: 44344
A11: SHAED-C | B11: SHAED-C010 | C11: 温湿度环境箱 | D11: 伟思富奇（太仓） | E11: C7-600E series | F11: W790 x D750 x H950mm=600L | G11: 徐东敏 | H11: 44372 | I11: 44736 | J11: 44555
A12: SHAED-C | B12: SHAED-C011 | C12: 温湿度环境箱 | D12: 伟思富奇（太仓） | E12: C7-600E series | F12: W790 x D750 x H950mm=600L | G12: 徐东敏 | H12: 44030 | I12: 44394 | J12: 44213
A13: SHAED-C | B13: SHAED-C012 | C13: 温湿度环境箱 | D13: 伟思富奇（太仓） | E13: C7-1000E series | F13: W1090 x D900 x H950mm=1000L | G13: 徐申扬 | H13: 44341 | I13: 44705 | J13: 44524
... A41: SHAED-H | B41: SHAED-H010 | C41: 高温箱 | D41: 无锡帕捷 | E41: PTC3005-D | F41: W800*D800*H800 | G41: 王皓冬 | H41: 44356 | I41: 44720 | J41: 44539
A42: SHAED-I | B42: SHAED-I002 | C42: JIS防水试验机 | D42: 台湾铁木真科技 | E42: TMJ-9710A | F42: W1000 x D1100 x H1000 | G42: 阮徐君 | H42: 44081 | I42: 44445 | J42: =H42+183 -> 44264
A43: SHAED-I | B43: SHAED-I003 | C43: 冰水冲击试验箱 | D43: 上海庆生 | E43: KTCE-018TBS | F43: W420 x D500 x H260 mm=60L | G43: 阮徐君 | H43: 44153 | I43: 44517 | J43: =H43+183 -> 44336
A44: SHAED-I | B44: SHAED-I004 | C44: 防尘箱 | D44: 台湾铁木真科技 | E44: KTM-DT90F | F44: W1000 x D1000 x H1000mm=1000L 小于等于20kg | G44: 唐播甜 | H44: 44372 | I44: 44736 | J44: =H44+183 -> 44555
A45: SHAED-I | B45: SHAED-I005 | C45: 防尘箱 | D45: 东莞昌鸿 | E45: CH-7139-C | F45: W1000 x D1000 x H1000mm=1000L 小于等于20kg | G45: 唐播甜 | H45: 44372 | I45: 44736 | J45: =H45+183 -> 44555
A46: SHAED-I | B46: SHAED-I006 | C46: 防尘箱 | D46: 东莞昌鸿 | E46: CH-7139-F | F46: W1000 x D1000 x H1000mm=1000L 小于等于20kg | G46: 唐播甜 | H46: 44030 | I46: 44394 | J46: =H46+183 -> 44213
A47: SHAED-I | B47: SHAED-I007 | C47: 冰水冲击试验箱-飞溅 | D47: 帕捷Partner | E47: PTC2018-DU-SPRAY | F47: W1500 x D1050 x H1200mm=2000L | G47: 阮徐君 | H47: 44340 | I47: 44704 | J47: =H47+183 -> 44523
A48: SHAED-I | B48: SHAED-I008 | C48: 冰水冲击试验箱-浸没 | D48: 帕捷Partner | E48: TSLA030SA | F48: W540 x D540 x H540 mm=160L | G48: 阮徐君 | H48: 44299 | I48: 44663 | J48: =H48+183 -> 44482
A49: SHAED-I | B49: SHAED-I009 | C49: IP防水试验机 | D49: 凯驰 | E49: HDS13/20-4S | F49: NA | G49: 阮徐君 | H49: 44341 | I49: 44705 | J49: =H49+183 -> 44524
A50: SHAED-I | B50: SHAED-I011 | C50: 粉尘筛 | D50: NA | E50: 200目 | F50: NA | G50: 唐播甜 | H50: 44133 | I50: 44497 | J50: =H50+183 -> 44316
A51: SHAED-I | B51: SHAED-I012 | C51: 压力表-IPX5X69K | E51: MIK-Y190 | G51: 阮徐君 | H51: 44306 | I51: 44670 | J51: =H51+183 -> 44489
A52: SHAED-Q | B52: SHAED-Q001 | C52: 快速温度变化试验箱 | D52: 伟思富奇（太仓） | E52: C7-800/15 ESS | F52: W1050 x D750 x H900mm=800L | G52: 蒋诗果 | H52: 44341 | I52: 44705 | J52: 44524
A53: SHAED-Q | B53: SHAED-Q002 | C53: 快速温度变化试验箱 | D53: 伟思富奇（太仓） | E53: C7-800/15 ESS | F53: W1050 x D750 x H900mm=800L | G53: 蒋诗果 | H53: 44330 | I53: 44694 | J53: 44513
A54: SHAED-Q | B54: SHAED-Q003 | C54: 快速温度变化试验箱 | D54: 伟思富奇（太仓） | E54: C7-800/15 ESS | F54: W1050 x D750 x H900mm=800L | G54: 蒋诗果 | H54: 44309 | I54: 44673 | J54: 44492
A55: SHAED-Q | B55: SHAED-Q004 | C55: 快速温度变化试验箱 | D55: 伟思富奇（太仓） | E55: C7-800/15 ESS | F55: W1050 x D750 x H900mm=800L | G55: 蒋诗果 | H55: 44266 | I55: 44630 | J55: 44449
A56: SHAED-Q | B56: SHAED-Q005 | C56: 快速温度变化试验箱 | D56: 帕捷Partner | E56: PHR720W-20 | F56: W2000 x D1000 × H1000=2000L | G56: 蒋诗果 | H56: 44266 | I56: 44630 | J56: 44449
A57: SHAED-Q | B57: SHAED-Q006 | C57: 快速温度变化试验箱 | D57: 伟思富奇（太仓） | E57: C7-480/20 ESS | F57: W800 x D640 × H940=480L | G57: 蒋诗果 | H57: 44330 | I57: 44694 | J57: 44513
A58: SHAED-Q | B58: SHAED-Q007 | C58: 快速温度变化试验箱 | D58: 伟思富奇（太仓） | E58: C7-1300/20 ESS | F58: W1100 x D1300 × H900=1300L | G58: 傅强 | H58: 44330 | I58: 44694 | J58: 44513
A59: SHAED-Q | B59: SHAED-Q008 | C59: 快速温度变化试验箱 | D59: 帕捷Partner | E59: PHR710W-2020 | F59: W1000 x D1000 × H1000=1000L | G59: 傅强 | H59: 44372 | I59: 44736 | J59: 44555
A60: SHAED-Q | B60: SHAED-Q009 | C60: 快速温度变化试验箱 | D60: 帕捷Partner | E60: PHR710W-2020 | F60: W1000 x D1000 × H1000=1000L | G60: 傅强 | H60: 44372 | I60: 44736 | J60: 44555
A61: SHAED-S | B61: SHAED-S001 | C61: 温度冲击试验箱 | D61: 广州五所环境仪器有限公司 | E61: TS-120SW | F61: W470 × D650 × H407mm=120L | G61: 李耀辉 | H61: 44308 | I61: 44672 | J61: 44491
A62: SHAED-S | B62: SHAED-S002 | C62: 温度冲击试验箱 | D62: 广州五所环境仪器有限公司 | E62: TS-300SW | F62: W770 × D650 x H610mm=300L | G62: 李耀辉 | H62: 44265 | I62: 44629 | J62: 44448
A63: SHAED-S | B63: SHAED-S003 | C63: 温度冲击试验箱 | D63: 广州五所环境仪器有限公司 | E63: TS-300SW | F63: W770 × D650 x H610mm=300L | G63: 李耀辉 | H63: 44125 | I63: 44489 | J63: 44308
... A69: SHAED-S | B69: SHAED-S009 | C69: 温度冲击试验箱 | D69: 帕捷Partner | E69: TSV6455A | F69: W350 × D340 × H350mm | G69: 王皓冬 | H69: 44340 | I69: 44704 | J69: 44523

Sheet 转出设备
B1: 设备类型 | C1: 设备编号 | D1: 内部编号 | E1: 出厂编号 | F1: 设备名称 | G1: 制造厂商 | H1: 型号 | I1: 设备尺寸 | J1: 主要参数 | K1: 采购供应商 | L1: 到货日期 | M1: 负责人 | N1: 使用人授权最低类别 | O1: 校准机构 | P1: 校准有效期 | Q1: 校准时间 | R1: 计划校准时间
B2: SHAED-E | C2: SHAED-E002 | D2: TTE20131907 | E2: 1307963019 | F2: 交直流耐压绝缘测试仪 | G2: 青岛艾诺 | H2: AN9636S | I2: NA | J2: 输出电压：100v-5000vac（注：an9636s最高电压达到6000vac)；输出电压负载调整率：±（2%×设定值+5v），空载→额定负载；最大额定负载：6000v/80ma；高压变压器容量：500va；最小短路电流：200ma； | K2: 上海振莺机电设备有限公司 | L2: 2013 | O2: CTI | P2: 一年 | Q2: 43724 | R2: 44089 | S2: 转材料
B3: SHAED-P | C3: SHAED-P005 | D3: TTF20170470 | E3: 602592010727150013 | F3: 可编程直流电源 | G3: 美国艾德克斯ITECH | H3: IT6164B | I3: NA | J3: 输出电压：0-30V/0-60V；输出电流：0-40A/0-20A；输出功率：1200W | K3: 深圳市科瑞杰科技有限公司 | L3: 2017 | O3: CTI | P3: 一年 | Q3: 43724 | R3: 44089 | S3: 转材料
B4: SHAED-O | C4: SHAED-O001 | D4: TTE20176057 | E4: 170523682 | F4: 照度计 | G4: 日本日置HIOKI | H4: FT3424 | J4: （0.00~200000）lx±2%rdg 用于照明设备、照明施工等领域 | K4: 科电贸易（上海）有限公司 | L4: 2017 | O4: 上海计量院 | P4: 一年 | Q4: 44081 | R4: 44445 | S4: 转材料
B5: SHAED-O | C5: SHAED-O002 | D5: TTE20176061 | E5: 00770792 | F5: 噪声计 | G5: 日本日置HIOKI | H5: FT3432 | J5: 30dB 到 130dB | K5: 科电贸易（上海）有限公司 | L5: 2017 | O5: 上海计量院 | P5: 一年 | Q5: 43735 | R5: 44100 | S5: 转材料
B6: SHAED-P | C6: SHAED-P031 | D6: TTF20120286 | E6: 1166610001 | F6: 可编程直流电源 | G6: Elektro-Automatik | H6: PSI 8080-60 | I6: NA | J6: 0~80V， 0~60A， 0~1500W | K6: 上海盛恒机电设备有限公司 | O6: CTI | Q6: 43724 | R6: 44089 | S6: 转材料
B7: SHAED-P | C7: SHAED-P042 | D7: TTF20180978 | E7: 1807538003H | F7: 直流电源 | G7: 山东艾诺Ainuo | H7: AN5380-170 | I7: NA | J7: 0~80V，0~170A，0~5000W | Q7: 43724 | R7: 44089 | S7: 转材料
B8: SHAED-P | C8: SHAED-P043 | D8: TTF20181681 | E8: 1809538002 | F8: 直流电源 | G8: 山东艾诺Ainuo | H8: AN5380-510 | I8: NA | J8: 0~80V，0~510A，0~15000W | Q8: 43724 | R8: 44089 | S8: 转材料
B9: SHAED-P | C9: SHAED-P044 | D9: TTF20190004 | E9: 1810538010A | F9: 直流电源 | G9: 山东艾诺Ainuo | H9: AN5380-170 | I9: NA | J9: 0~80V，0~170A，0~5000W | Q9: 43724 | R9: 44089 | S9: 转材料
B10: SHAED-P | C10: SHAED-P045 | D10: TTF20190005 | E10: 1812538008 | F10: 直流电源 | G10: 山东艾诺Ainuo | H10: AN5380-170 | I10: NA | J10: 0~80V，0~170A，0~5000W | Q10: 43724 | R10: 44089 | S10: 转材料
B12: SHAED-X | C12: SHAED-X008 | D12: TTE20200916 | E12: NA | F12: 2.5次元尺寸测量仪 | H12: MS400 | L12: 2020 | Q12: 44085 | R12: 44449 | S12: 转材料 | T12: 设备在材料，实际已转材料，但帐挂在汽车电子，下次材料自己校准
B15: SHAED-O | C15: SHAED-O038 | D15: 低值 | E15: NA | F15: 转速计 | G15: 优利德 | H15: UT373 | I15: NA | L15: 2020 | M15: 唐播甜 | N15: A | O15: CTI | P15: 一年 | S15: 待确认 已买更精确设备，停用此设备

Sheet 负责人名单
A1: 目前使用人 | B1: 设备使用结束时间 | C1: 设备类型 | D1: 设备编号 | E1: 内部编号 | F1: 出厂编号 | G1: 设备名称 | H1: 制造厂商 | I1: 型号 | J1: 到货日期 | K1: 负责人 | L1: 使用人授权 | M1: 校准机构 | N1: 校准有效期 | O1: 校准时间 | P1: 计划校准时间
A2: 李耀辉 | C2: 没有在用电源
A3: 王贺 | C3: 没有在用电源
A4: 王林华 | C4: 没有在用电源
A5: 张杰 | C5: 没有在用电源
A6: 蒋诗果 | C6: 没有在用电源
A7: 唐播甜 | C7: 没有在用电源
C8: 没有在用电源
C9: 没有在用电源
A10: 李耀辉 | C10: 没有在用记录仪
A11: 阮徐君 | C11: 没有在用记录仪
A12: 徐申扬 | C12: 没有在用记录仪
A13: 唐播甜 | C13: 没有在用记录仪
A14: 王贺 | C14: 没有在用记录仪
A15: 王林华 | C15: 没有在用记录仪
A16: 张杰 | C16: 没有在用记录仪
A17: 梁健宇 | C17: 没有在用记录仪
C18: SHAED-P | D18: SHAED-P001 | E18: TTE20160719 | F18: WA002723 | G18: 可编程直流电源 | H18: 日本菊水KIKUSUI | I18: PBZ20-20 | J18: 2016 | K18: 祝亦杰 | M18: CTI | N18: 一年 | O18: 44081 | P18: 44445
A19: 阮徐君 | B19: 2021.01.02 | C19: SHAED-P | D19: SHAED-P002 | E19: TTE20165250 | F19: WB001609 | G19: 可编程直流电源 | H19: 日本菊水KIKUSUI | I19: PBZ20-20 | J19: 2016 | K19: 祝亦杰 | M19: CTI | N19: 一年 | O19: 44081 | P19: 44445
C20: SHAED-P | D20: SHAED-P003 | E20: TTE20165251 | F20: WC002180 | G20: 可编程直流电源 | H20: 日本菊水KIKUSUI | I20: PBZ20-20 | J20: 2016 | K20: 徐东敏 | M20: CTI | N20: 一年 | O20: 44081 | P20: 44445
C21: SHAED-P | D21: SHAED-P004 | E21: TTF20140003 | F21: TM001786 | G21: 可编程直流电源 | H21: 日本菊水KIKUSUI | I21: PBZ40-10 | J21: 2014 | K21: 徐东敏 | M21: CTI | N21: 一年 | O21: 44081 | P21: 44080
A22: 材料 | C22: SHAED-P | D22: SHAED-P005 | E22: TTF20170470 | F22: 602592010727150013 | G22: 可编程直流电源 | H22: 美国艾德克斯ITECH | I22: IT6164B | J22: 2017 | K22: 许宇峰 | M22: CTI | N22: 一年 | O22: 43724 | P22: 44089
C23: SHAED-P | D23: SHAED-P006 | E23: TTF20170477 | F23: XH002048 | G23: 直流电源 | H23: 日本菊水KIKUSUI | I23: PAV36-12 | J23: 2017 | K23: 许宇峰 | M23: CTI | N23: 一年 | O23: 43724 | P23: 44088
C24: SHAED-P | D24: SHAED-P007 | E24: TTF20170478 | F24: XH002047 | G24: 直流电源 | H24: 日本菊水KIKUSUI | I24: PAV36-12 | J24: 2017 | K24: 许宇峰 | M24: 上海质检院 | N24: 一年 | O24: 43391 | P24: 43755
C25: SHAED-P | D25: SHAED-P008 | E25: TTF20170479 | F25: XH002046 | G25: 直流电源 | H25: 日本菊水KIKUSUI | I25: PAV36-12 | J25: 2017 | K25: 许宇峰 | M25: CTI | N25: 一年 | O25: 44118 | P25: 44482
C26: SHAED-P | D26: SHAED-P009 | E26: TTF20170480 | F26: XL001771 | G26: 直流电源 | H26: 日本菊水KIKUSUI | I26: PAV650-1 | J26: 2017 | K26: 许宇峰 | M26: 上海质检院 | N26: 一年 | O26: 43444 | P26: 43808
C27: SHAED-P | D27: SHAED-P010 | E27: TTF20170481 | F27: XL001772 | G27: 直流电源 | H27: 日本菊水KIKUSUI | I27: PAV650-1 | J27: 2017 | K27: 许宇峰 | M27: CTI | N27: 一年 | O27: 44118 | P27: 44482
A28: 梁健宇 | B28: 2020.10.21 | C28: SHAED-P | D28: SHAED-P011 | E28: TTF20190902 | F28: 802259072747200023 | G28: 直流电源 | H28: 美国艾德克斯ITECH | I28: IT6722A | J28: 2019 | K28: 梁健宇 | M28: CTI | N28: 一年 | O28: 44118 | P28: 44482
A29: 盐雾任亮借用 | C29: SHAED-P | D29: SHAED-P012 | E29: TTF20190903 | F29: 802259072747110041 | G29: 直流电源 | H29: 美国艾德克斯ITECH | I29: IT6722A | J29: 2019 | K29: 梁健宇 | M29: CTI | N29: 一年 | O29: 44118 | P29: 44482
A30: 阮徐君 | B30: 2020.12.30 | C30: SHAED-P | D30: SHAED-P013 | E30: TTF20190904 | F30: 802259072747210050 | G30: 直流电源 | H30: 美国艾德克斯ITECH | I30: IT6722A | J30: 2019 | K30: 梁健宇 | M30: CTI | N30: 一年 | O30: 44118 | P30: 44482
A31: 盐雾任亮借用 | C31: SHAED-P | D31: SHAED-P014 | E31: TTF20190905 | F31: 802259072747210071 | G31: 直流电源 | H31: 美国艾德克斯ITECH | I31: IT6722A | J31: 2019 | K31: 阮徐君 | M31: CTI | N31: 一年 | O31: 43761 | P31: 44125
A32: 徐东敏 | B32: 2020.11.01 | C32: SHAED-P | D32: SHAED-P015 | E32: TTF20190906 | F32: 802259072747210094 | G32: 直流电源 | H32: 美国艾德克斯ITECH | I32: IT6722A | J32: 2019 | K32: 阮徐君 | M32: CTI | N32: 一年 | O32: 44118 | P32: 44482
A33: 黄骏 | B33: 2020.12.25 | C33: SHAED-P | D33: SHAED-P016 | E33: TTF20190907 | F33: 802259072747210074 | G33: 直流电源 | H33: 美国艾德克斯ITECH | I33: IT6722A | J33: 2019 | K33: 阮徐君 | M33: CTI | N33: 一年 | O33: 44118 | P33: 44482
C34: SHAED-P | D34: SHAED-P017 | E34: TTF20190908 | F34: 802259072747110031 | G34: 直流电源 | H34: 美国艾德克斯ITECH | I34: IT6722A | J34: 2019 | K34: 徐东敏 | M34: CTI | N34: 一年 | O34: 44118 | P34: 44482
C35: SHAED-P | D35: SHAED-P018 | E35: TTF20190909 | F35: 802259072747110035 | G35: 直流电源 | H35: 美国艾德克斯ITECH | I35: IT6722A | J35: 2019 | K35: 徐东敏 | M35: CTI | N35: 一年 | O35: 43761 | P35: 44125
C36: SHAED-P | D36: SHAED-P019 | E36: TTF20190929 | F36: 802125114747410003 | G36: 直流电源 | H36: 美国艾德克斯ITECH | I36: IT6724 | J36: 2019 | K36: 徐东敏 | M36: CTI | N36: 一年 | O36: 44081 | P36: 44445
A37: 祝亦杰 | B37: 2020.10.24 | C37: SHAED-P | D37: SHAED-P020 | E37: TTF20190930 | F37: 802169114747110006 | G37: 直流电源 | H37: 美国艾德克斯ITECH | I37: IT6723 | J37: 2019 | K37: 祝亦杰 | M37: CTI | N37: 一年 | O37: 44081 | P37: 44445
A38: 黄骏 | B38: 2020.12.25 | C38: SHAED-P | D38: SHAED-P021 | E38: TTF20190931 | F38: 802169114747110017 | G38: 直流电源 | H38: 美国艾德克斯ITECH | I38: IT6723 | J38: 2019 | K38: 祝亦杰 | M38: CTI | N38: 一年 | O38: 44081 | P38: 44445
A39: 徐申扬 | B39: 2020.10.22 | C39: SHAED-P | D39: SHAED-P022 | E39: TTF20190932 | F39: 802169114747230024 | G39: 直流电源 | H39: 美国艾德克斯ITECH | I39: IT6723 | J39: 2019 | K39: 祝亦杰 | M39: CTI | N39: 一年 | O39: 44081 | P39: 44445
A40: 阮徐君 | B40: 2020.12.19 | C40: SHAED-P | D40: SHAED-P023 | E40: TTF20190933 | F40: 802169114747110016 | G40: 直流电源 | H40: 美国艾德克斯ITECH | I40: IT6723 | J40: 2019 | K40: 黄骏 | M40: CTI | N40: 一年 | O40: 44081 | P40: 44445
...

Sheet 外借设备
A1: 外借时间 | B1: 计划归还时间 | C1: 实际归还时间 | D1: 设备信息 | E1: 需求人 | F1: 借出人
A2: 44081 | B2: 11月 | C2: 44138 | D2: 大电源一台 | E2: 苏州杨芳芳 | F2: 李赫
A3: 44134 | B3: 11月中旬 | C3: 44166 | D3: CAN盒一个 | E3: EMC 宋斌 | F3: 李赫
A4: 44105 | B4: 不确定 | C4: 44217 | D4: CAN盒一个 | F4: 王子翼
A5: 44148 | B5: 44389 | D5: DAQ970A+3块板卡 | E5: 广州 黎炽雄 | F5: 黄骏
A6: 44151 | B6: 不确定 | C6: 44403 | D6: SHAED-E007电流钳 | E6: 武汉汽车 田易萍 | F6: 许宇峰
A7: 44169 | B7: 44183 | D7: SHAED-P015直流电源 | E7: 材料盐雾 任亮 | F7: 许宇峰
A8: 44210 | B8: 不确定 | D8: TTE20176501 | E8: 材料 吴逸君 | F8: 许宇峰
A9: 44231 | B9: 44232 | C9: 44237 | D9: TTF20200420直流电源 | E9: 庞训停 | F9: 黄骏
A10: 44231 | B10: 44232 | C10: 44237 | D10: TTF20200419直流电源 | E10: 庞训停 | F10: 黄骏
A11: 44231 | B11: 44232 | C11: 44237 | D11: TTF20190903直流电源 | E11: 庞训停 | F11: 黄骏
A12: 44231 | B12: 44232 | C12: 44237 | D12: TTF20201088直流电源 | E12: 庞训停 | F12: 黄骏
A13: 44231 | B13: 44232 | C13: 44237 | D13: TTF20190905直流电源 | E13: 庞训停 | F13: 黄骏
A14: 44231 | B14: 44232 | C14: 44237 | D14: SHAED-P002可编程 | E14: 庞训停 | F14: 黄骏
A15: 44231 | B15: 44232 | C15: 44237 | D15: SHAED-P003可编程 | E15: 庞训停 | F15: 黄骏
A16: 44287 | B16: 44301 | C16: 44355 | D16: SHAED-P021 | E16: 芯片实验室 | F16: 许宇峰
A17: 44287 | B17: 44301 | C17: 44355 | D17: SHAED-P026 | E17: 芯片实验室 | F17: 许宇峰
A18: 44294 | B18: =A18+42 -> 44336 | C18: 44377 | D18: SHAED-P007 | E18: 材料黄鹏飞 | F18: 李赫
A19: 44294 | B19: =A19+42 -> 44336 | C19: 44377 | D19: SHAED-P008 | E19: 材料黄鹏飞 | F19: 李赫
A20: 44295 | D20: SHAED-P010 | E20: 广州电池蔡工 | F20: 许宇峰
A21: 44305 | D21: SHAED-P030 | E21: 苏州沈工 | F21: 许宇峰
A22: 44326 | C22: 44357 | D22: SHAED-P050 | E22: 材料盐雾 任亮 | F22: 许宇峰
A23: 44328 | D23: SHAED-E011 | E23: 苏州杨芳芳 | F23: 张杰
A24: 44334 | D24: SHAED-R014 | E24: CR陶园园 | F24: 许宇峰
A25: 44370 | B25: 44375 | D25: P034 | E25: 任亮 | F25: 许宇峰
A26: 44379 | B26: 44386 | C26: 44403 | D26: R007 | E26: 通敏-张黎春 | F26: 许宇峰
A27: 44396 | B27: 44418 | D27: SHAED-P020 | E27: 材料 吴逸君 | F27: 许宇峰
A28: 44396 | B28: 44418 | D28: TTE20211113 | E28: 材料 吴逸君 | F28: 许宇峰
A29: 44641 | B29: 44645 | D29: P075 | E29: 材料 吴逸君 | F29: 黄骏
D48: 未找到电源
D49: SHAED-P048
D50: SHAED-R013

Sheet 下拉列表
B2: 内部编号 | C2: 设备名称 | D2: 型号 | E2: 制造厂商 | F2: 设备位置 | G2: 负责人 | H2: 出厂编号 | I2: 采购供应商 | J2: 价格（扣除税点） | K2: 到货日期 | L2: 校准状态
L3: 现场-等待校准
A4: SHAED-C | C4: 温湿度环境箱 | E4: 美国福禄克Fluke | F4: 新2楼环境 | G4: 张建 | I4: 伟思富奇 | L4: 现场-已校准报告未到
A5: SHAED-C | C5: 温湿度环境箱-Pro | E5: 美国是德Keysight | F5: 新2楼线束 | G5: 王子翼 | I5: 苏盈 | L5: 现场-已拿到报告并核对好
A6: SHAED-C | C6: 温湿度环境箱-匹配振动台 | E6: 史丹利STANLEY | F6: 新2楼仓库 | G6: 许宇峰 | I6: 广五所
A7: SHAED-E | C7: 示波器 | E7: 日本耐苛NAC | F7: 新1楼 | G7: 黄骏 | I7: 成测 | L7: 送校-已送未反馈
A8: SHAED-E | C8: 六位半万用表 | E8: 美国艾德克斯ITECH | G8: 李赫 | I8: 重庆阿泰可 | L8: 送校-已送但有问题
A9: SHAED-E | C9: 电子负载 | E9: 日本菊水KIKUSUI | G9: 徐申扬 | I9: 深圳市世纪通供应链股份有限公司 | L9: 送校-已送收到设备、证书并核对好
A10: SHAED-E | C10: 瞬断仪 | E10: 杭州美仪 | G10: 李耀辉
A11: SHAED-E | C11: 电流钳 | E11: 日本日置HIOKI | G11: 王菁
A12: SHAED-E | C12: 七位半万用表 | E12: Bruel&Kjaer | G12: 阮徐君
A13: SHAED-E | C13: 交直流耐压绝缘测试仪 | E13: 世达SATA | G13: 李光华
A14: SHAED-E | C14: 存储记录仪（示波器） | E14: 优利德 | G14: 徐东敏
A15: SHAED-E | C15: 数字万用表 | E15: Elektro-Automatik | G15: 祝亦杰
A16: SHAED-E | C16: LCR表 | E16: 重庆阿泰可 | G16: 张杰
A17: SHAED-E | C17: 电性能综合测试系统 | E17: 瑞士emtest
A18: SHAED-E | E18: Faith
A19: SHAED-E | C19: CANoe模块 | E19: 德国Vector
A20: SHAED-E | C20: 旋转式电阻箱 | E20: 澄洋仪器
A21: SHAED-H | C21: 高温试验箱 | E21: TESTO
A22: SHAED-I | C22: IP防水试验机 | E22: 远方
A23: SHAED-I | C23: JIS防水试验机 | E23: 东莞昌鸿
A24: SHAED-I | C24: 两厢式冰水冲击试验箱-喷淋 | E24: 帕捷Partner
A25: SHAED-I | C25: 两厢式冰水冲击试验箱-浸水 | E25: 力新宝
A26: SHAED-I | C26: 两厢式冰水冲击试验箱-喷淋/浸水 | E26: 美特斯工业系统（中国）有限公司
A27: SHAED-I | C27: 防尘箱 | E27: GRA日本图技PHTEC
A28: SHAED-I | C28: 粉尘筛
A29: SHAED-I | C29: 高压清洗机 | E29: 凯驰
A30: SHAED-O | C30: 照度计 | E30: 泛德声学
A31: SHAED-O | C31: 噪声计 | E31: 山东艾诺Ainuo
A32: SHAED-O | C32: 亮度计 | E32: Elektro-Automatik
A33: SHAED-O | C33: 成像亮度计 | E33: 无锡南亚
A34: SHAED-O | C34: 光谱亮度计 | E34: Fluke
A35: SHAED-O | C35: 热像仪 | E35: 温州一鼎
A36: SHAED-O | C36: 声级计 | E36: NA
A37: SHAED-O | C37: 静音房 | E37: Tektronix
A38: SHAED-O | C38: 数显扭矩扳手1.5-30N.m | E38: 安捷伦
A39: SHAED-O | C39: 数显扭矩扳手10-200N.m | E39: 欧姆龙
A40: SHAED-O | C40: 游标卡尺 | E40: 艾诺
... A45: SHAED-O | C45: 转速计 | E45: 联测
...

Sheet 文件要求
A2: 1 | B2: 新设备：有校准报告时更新此表格信息（包括固定资产设备、其他低值测试工具），可能未生成设备系统号
A3: 2 | B3: 在用设备：校准信息等更新时，更新此表格
A4: 3 | B4: 每月15日左右核对表格状态

Sheet 设备基本信息
A1: 设备名称 | B1: 品牌 | C1: 数量
A2: 高温箱 | B2: 苏盈 | C2: 8
A3: 环境箱 | B3: 伟思 | C3: 18
B4: 广五所 | C4: 3
B5: 阿泰可 | C5: 3
A6: 快速温变箱 | B6: 伟思 | C6: 4
B7: 帕捷 | C7: 1
A8: 温度冲击箱 | B8: 广五所 | C8: 6
B9: 阿泰可 | C9: 1
A10: 三综合振动台 | B10: 航天希尔 | C10: 6
A11: 机械冲击台 | B11: 航天希尔 | C11: 2
A12: 直流电源 | B12: 美国艾德克斯ITECH | C12: 34
A13: 可编程 | B13: 日本菊水 | C13: 9
A14: 大功率电源 | B14: Elektro-Automatik | C14: 5
B15: 山东艾诺Ainuo | C15: 4
A16: 记录仪 | B16: 日置HIOKI | C16: 22
B17: 图技 | C17: 4
A18: 数采 | B18: 美国是德Keysight | C18: 2
A19: 示波器 | B19: 美国泰克Tek | C19: 2
A20: 瞬断仪 | B20: 日本耐苛NAC | C20: 3
A21: 电性能综合测试系统 | B21: 瑞士emtest | C21: 1
A22: 拉伸机 | B22: MTS | C22: 1
A23: 七位半万用表 | B23: 美国是德Keysight | C23: 1
A24: 电流钳 | B24: 日置HIOKI | C24: 8
A25: 电子负载 | B25: 美国艾德克斯ITECH | C25: 8

Sheet 笔记本
A1: 编号 | B1: 设备编号 | C1: 名称 | D1: 品牌 | E1: 型号 | F1: 备注
A2: SHAED-LX001 | C2: 笔记本 | D2: 联想 | E2: E14 Gen4 | F2: 按键试验机专用
A3: SHAED-HJ001 | B3: ODN20231003 | C3: 笔记本 | D3: 宏基 | E3: 未来，14英寸 12代酷睿i5 16G 512G
A4: SHAED-HJ002 | B4: ODN20231004 | C4: 笔记本 | D4: 宏基 | E4: 未来，14英寸 12代酷睿i5 16G 512G
A5: SHAED-HJ003 | B5: ODN20231005 | C5: 笔记本 | D5: 宏基 | E5: 未来，14英寸 12代酷睿i5 16G 512G
A6: SHAED-HJ004 | B6: ODN20240687 | C6: 笔记本 | D6: 宏基 | E6: 宏碁优跃 14英寸 13代酷睿i5 16G 1T
A7: SHAED-HJ005 | B7: ODN20240688 | C7: 笔记本 | D7: 宏基 | E7: 宏碁优跃 14英寸 13代酷睿i5 16G 1T
A8: SHAED-HJ006 | B8: ODN20240689 | C8: 笔记本 | D8: 宏基 | E8: 宏碁优跃 14英寸 13代酷睿i5 16G 1T
A9: SHAED-HJ007 | B9: ODN20240690 | C9: 笔记本 | D9: 宏基 | E9: 宏碁优跃 14英寸 13代酷睿i5 16G 1T
A10: SHAED-HJ008 | B10: ODN20240691 | C10: 笔记本 | D10: 宏基 | E10: 宏碁优跃 14英寸 13代酷睿i5 16G 1T
A11: SHAED-HJ009 | B11: ODN20240692 | C11: 笔记本 | D11: 宏基 | E11: 宏碁优跃 14英寸 13代酷睿i5 16G 1T

Sheet CAN
A1: 设备编号 | B1: 内部编号 | C1: 设备名称 | D1: 出厂编号 | E1: 制造厂商 | F1: 型号 | G1: 到货日期
A2: PCAN001 | B2: TTF202604222 | C2: CAN盒 | D2: NA | E2: PEAK | F2: IPEH-004064 | G2: 2026
A3: PCAN002 | B3: TTF202604224 | C3: CAN盒 | D3: NA | E3: PEAK | F3: IPEH-004064 | G3: 2026
A4: PCAN003 | B4: TTF202604225 | C4: CAN盒 | D4: NA | E4: PEAK | F4: IPEH-004064 | G4: 2026
A5: PCAN004 | B5: TTF202604227 | C5: CAN盒 | D5: NA | E5: PEAK | F5: IPEH-004064 | G5: 2026
A6: PCAN005 | B6: TTF202604230 | C6: CAN盒 | D6: NA | E6: PEAK | F6: IPEH-004064 | G6: 2026
A7: PCAN006 | B7: TTF202604231 | C7: CAN盒 | D7: NA | E7: PEAK | F7: IPEH-004064 | G7: 2026
A8: PCAN007 | B8: TTF202604232 | C8: CAN盒 | D8: NA | E8: PEAK | F8: IPEH-004064 | G8: 2026
A9: PCAN008 | B9: TTF202604233 | C9: CAN盒 | D9: NA | E9: PEAK | F9: IPEH-004064 | G9: 2026
A10: PCAN009 | B10: TTF202604234 | C10: CAN盒 | D10: NA | E10: PEAK | F10: IPEH-004064 | G10: 2026
A11: PCAN010 | B11: TTF202604236 | C11: CAN盒 | D11: NA | E11: PEAK | F11: IPEH-004064 | G11: 2026
A12: PCAN011 | B12: TTF202604237 | C12: CAN盒 | D12: NA | E12: PEAK | F12: IPEH-004064 | G12: 2026
A13: PCAN012 | B13: TTF202604240 | C13: CAN盒 | D13: NA | E13: PEAK | F13: IPEH-004064 | G13: 2026
